Workbook
Name _AN859833: '[1]DAILY SALES DATA'!#REF!
Name Excel_BuiltIn_Print_Area: NA()
Name Excel_BuiltIn_Print_Area: NA()
Name Excel_BuiltIn_Print_Area: NA()
Name Excel_BuiltIn_Print_Area_2_1: NA()
Name Excel_BuiltIn_Print_Area_22_1: NA()
Name Excel_BuiltIn_Print_Area_30_1: NA()
Name Excel_BuiltIn_Print_Area_37_1: NA()
Name Excel_BuiltIn_Print_Area_39: NA()
Name Excel_BuiltIn_Print_Area_41: NA()
Name Excel_BuiltIn_Sheet_Title: "Individual Commission"
Name Excel_BuiltIn_Sheet_Title: "01"
Name Excel_BuiltIn_Sheet_Title: "01"
Name Excel_BuiltIn_Sheet_Title: "01"
Name Excel_BuiltIn_Sheet_Title: "01"
Name Excel_BuiltIn_Sheet_Title: "01"
Name Excel_BuiltIn_Sheet_Title: "SPPR _"
Name Excel_BuiltIn_Sheet_Title: "Traffic "

Sheet DS
A1: BVLGARI – Plaza Indonesia
A2: Daily Sales Transaction Report
A3: Periode | B3: 46266
AE4: HARUS DI ISI | AG4: HARUS DI ISI
A5: Date | B5: CB No. | C5: Sales Invoice No | D5: Customer Name | E5: Cosmo CRM ID | F5: Nationality | G5: New | H5: Old | I5: W | J5: F | K5: Category | L5: SAP Code | M5: Item Name | N5: Serial No | O5: Description | P5: Qty | Q5: Gross Sales | R5: Disc. % | S5: Net Sales | T5: Discount Given Reason | U5: Payment | AC5: Achievement | AD5: Daily Total Achievement | AE5: Served By | AF5: CA | AG5: Entitle | AH5: After Sales Support | AI5: DWA | AJ5: Other Remarks
U6: Deposit CB No | V6: Rp. | W6: Card | X6: OR No. | Y6: Bank Transfer To | Z6: EDC | AA6: Card Type | AB6: Card Commission
A7: 46266 | B7: NO SALE | R7: =(Q7-S7)/Q7*100 -> #DIV/0! | AB7: =W7*1.3% -> 0 | AC7: =(S7/1.11) -> 0 | AD7: =SUM(AC7) -> 0
A8: 46267 | B8: CBPI 11389 | C8: INV-550/2609/02803 | D8: Monica Selly Agresia | E8: 13104490 | F8: Indonesia | H8: 1 | J8: 1 | K8: JEWELRY | L8: 351051 | M8: CL857315 | N8: XH1WXK | O8: CL DIVA PG-5.0grs 1DIA-0.03ct 24PAVE-0.44ct PENDANT | P8: 1 | Q8: 174500000 | R8: =(Q8-S8)/Q8*100 -> 0 | S8: 174500000 | W8: 150000000 | Z8: BCA | AA8: V/HSBC | AB8: =W8*1.3% -> 1950000 | AC8: =(S8/1.11) -> 1.5720721e+08 | AE8: AJ | AF8: AJ | AG8: AJ | AH8: 807567 | AI8: 806422
R9: =(Q9-S9)/Q9*100 -> #DIV/0! | W9: 24500000 | Z9: BCA | AA9: V/HSBC | AB9: =W9*1.3% -> 318500 | AC9: =(S9/1.11) -> 0 | AH9: 806856
R10: =(Q10-S10)/Q10*100 -> #DIV/0! | AB10: =W10*1.3% -> 0 | AC10: =(S10/1.11) -> 0 | AH10: 807617
R11: =(Q11-S11)/Q11*100 -> #DIV/0! | AB11: =W11*7% -> 0 | AC11: =(S11/1.11) -> 0 | AD11: =SUM(AC8:AC11) -> 1.5720721e+08 | AH11: 806422
A12: 46268 | B12: CBPI 11392 | C12: INV-PI/2609/02806 | D12: Frisca Kargito | E12: 13571594 | F12: Indonesia | H12: 1 | J12: 1 | K12: JEWELRY | L12: 359949 | M12: OR859929 | N12: AA0X04 | O12: OR SVI PG-8.6grs 10PAVE-0.18ct | P12: 1 | Q12: 107900000 | R12: =(Q12-S12)/Q12*100 -> 0 | S12: =Q12 -> 107900000 | T12: CASHBACK BCA RP 2,500,000 | V12: 54400000 | W12: 51000000 | X12: 6612 | Z12: BCA | AA12: V/BCA 12X | AB12: =W12*5% -> 2550000 | AC12: =(S12/1.11) -> 97207207 | AE12: SD | AF12: SD | AG12: SD | AH12: 807570 | AI12: 806422 | AJ12: CASHBACK BCA RP 2,500,000
R13: =(Q13-S13)/Q13*100 -> #DIV/0! | AB13: =W13*5% -> 0 | AC13: =(S13/1.11) -> 0 | AH13: 806856
R14: =(Q14-S14)/Q14*100 -> #DIV/0! | AB14: =W14*3% -> 0 | AC14: =(S14/1.11) -> 0 | AH14: 807617
B15: CBPI 11393 | C15: INV-PI/2609/02807 | D15: Lisa Lissa | E15: 13664581 | F15: Indonesia | G15: 1 | I15: 1 | K15: JEWELRY | L15: 360467 | M15: AN859915 | N15: ARXF26 | O15: AN SVI 1ROW WG-7.0grs 6PAVE-0.14ct Sz 51-53 | P15: 1 | Q15: 91700000 | R15: =(Q15-S15)/Q15*100 -> 0 | S15: =Q15 -> 91700000 | V15: =S15+S16+S17+S18 -> 1004300000 | Y15: BCA | AB15: =W15*5% -> 0 | AC15: =(S15/1.11) -> 82612613 | AE15: SK | AF15: SK | AG15: SK | AH15: 807617 | AI15: 806422 | AJ15: GV 0238
K16: JEWELRY | L16: 361239 | M16: CL860213 | N16: AM0596 | O16: CL SVI PG-38,9grs TITANIUM-1.2 8PAVE-0.41ct Sz 36 | P16: 1 | Q16: 527700000 | R16: =(Q16-S16)/Q16*100 -> 0 | S16: =Q16 -> 527700000 | AB16: =W16*5% -> 0 | AC16: =(S16/1.11) -> 4.7540541e+08 | AH16: 806857 | AI16: 806422
K17: JEWELRY | L17: 361780 | M17: OR860393 | N17: AHF366 | O17: OR DIVA PG-6.1grs 2DIA-0.07ct 2MOP-0.08 22PAVE-0.18ct | P17: 1 | Q17: 106000000 | R17: =(Q17-S17)/Q17*100 -> 0 | S17: =Q17 -> 106000000 | AB17: =W17*5% -> 0 | AC17: =(S17/1.11) -> 95495495 | AH17: 806855 | AI17: 806422
K18: JEWELRY | L18: 360155 | M18: BR859759 | N18: ASRN57 | O18: BR SVI 1ROW BANGLE WG-17.8grs TITANIUM-1.7 8PAVE-0.47ct Sz 15 | P18: 1 | Q18: 278900000 | R18: =(Q18-S18)/Q18*100 -> 0 | S18: =Q18 -> 278900000 | AB18: =W18*0.15% -> 0 | AC18: =(S18/1.11) -> 2.5126126e+08 | AH18: 807573 | AI18: 806422
R19: =(Q19-S19)/Q19*100 -> #DIV/0! | AB19: =W19*2.2% -> 0 | AC19: =(S19/1.11) -> 0 | AH19: 807568
R20: =(Q20-S20)/Q20*100 -> #DIV/0! | AB20: =W20*1.3% -> 0 | AC20: =(S20/1.11) -> 0 | AH20: 807570
R21: =(Q21-S21)/Q21*100 -> #DIV/0! | AB21: =W21*2.25% -> 0 | AC21: =(S21/1.11) -> 0 | AH21: 807566
B22: CBPI 11394 | C22: SI-550/2609/37758 | D22: Jhon Levis | E22: 13367243 | F22: Indonesia | H22: 1 | J22: 1 | K22: JEWELRY | L22: 345209 | M22: AN855116 | N22: T5LYTF | O22: AN SVI 1ROW WG-9.2grs 75PAVE-1.58cts Sz S | P22: 1 | Q22: 574000000 | R22: =(Q22-S22)/Q22*100 -> 0 | S22: 574000000 | U22: CBPI 11326 | AB22: =W22*1.5% -> 0 | AC22: =(S22/1.11) -> 5.1711712e+08 | AE22: DP | AF22: DP | AG22: DP | AH22: 807617 | AI22: 806422 | AJ22: HOME DELIVERY
R23: =(Q23-S23)/Q23*100 -> #DIV/0! | AB23: =W23*1.4% -> 0 | AC23: =(S23/1.11) -> 0 | AH23: 806857 | AJ23: 80 : 20 (MM & HS)
R24: =(Q24-S24)/Q24*100 -> #DIV/0! | AB24: =W24*1.5% -> 0 | AC24: =(S24/1.11) -> 0 | AH24: 806856
R25: =(Q25-S25)/Q25*100 -> #DIV/0! | AB25: =W25*1.3% -> 0 | AC25: =(S25/1.11) -> 0 | AH25: 808138
B26: CBPI 11395 | C26: INV-550/2609/02811 | D26: Tiara Rinardi | E26: 13167381 | F26: Indonesia | H26: 1 | J26: 1 | K26: JEWELRY | L26: 360153 | M26: BR859759 | N26: AFH458 | O26: BR SVI 1ROW BANGLE WG-19.9grs TITANIUM-2.2 8PAVE-0.47ct Sz 17 | P26: 1 | Q26: 273000000 | R26: =(Q26-S26)/Q26*100 -> 0 | S26: 273000000 | U26: CBPI 11354 | AB26: =W26*0.15% -> 0 | AC26: =(S26/1.11) -> 2.4594595e+08 | AE26: HS | AF26: HS | AG26: HS | AH26: 806857 | AI26: 806422
R27: =(Q27-S27)/Q27*100 -> #DIV/0! | AB27: =W27*1.5% -> 0 | AC27: =(S27/1.11) -> 0 | AH27: 807617
R28: =(Q28-S28)/Q28*100 -> #DIV/0! | AB28: =W28*1.5% -> 0 | AC28: =(S28/1.11) -> 0 | AD28: =SUM(AC12:AC28) -> 1.765045e+09 | AH28: 807568
A29: 46269 | B29: CBPI 11397 | C29: SI-PI/2609/37768 | D29: Meksi Damara | E29: 13667214 | F29: Indonesia | M29: DEPOSIT | O29: DEPOSIT FULL PAYMENT RSI (349634 - ASP166) | R29: =(Q29-S29)/Q29*100 -> #DIV/0! | V29: 14800000 | Y29: BCA | AB29: =W29*1.4% -> 0 | AC29: =(S29/1.11) -> 0 | AE29: AL | AF29: AL
B30: CBPI 11398 | C30: INV-PI/2609/02814 | D30: Wina NR | E30: 13322899 | F30: Indonesia | H30: 1 | J30: 1 | K30: JEWELRY | L30: 348320 | M30: OR856498 | N30: AMT981 | O30: OR SER VIPER WG-18.6grs 112PAVE-2.08cts | P30: 1 | Q30: 792300000 | R30: =(Q30-S30)/Q30*100 -> 10 | S30: 713070000 | T30: DISC APP MS JESSICA | V30: =S30+S31 -> 1490490000 | X30: 6613 | AB30: =W30*1.3% -> 0 | AC30: =(S30/1.11) -> 6.4240541e+08 | AE30: SD | AF30: SD | AG30: SD | AH30: 808138 | AI30: 806422 | AJ30: HOME DELIVERY
K31: JEWELRY | L31: 347594 | M31: AN856156 | N31: A8RLX4 | O31: AN SVI 2ROWS PG-14.4grs 1RBLT-0.28 122HEADPAVE- 2.42cts Sz M | P31: 1 | Q31: 863800000 | R31: =(Q31-S31)/Q31*100 -> 10 | S31: 777420000 | AB31: =W31*1.3% -> 0 | AC31: =(S31/1.11) -> 7.0037838e+08 | AH31: 807570 | AI31: 806422
R32: =(Q32-S32)/Q32*100 -> #DIV/0! | AB32: =W32*2.25% -> 0 | AC32: =(S32/1.11) -> 0 | AH32: 804190
R33: =(Q33-S33)/Q33*100 -> #DIV/0! | AB33: =W33*0.15% -> 0 | AC33: =(S33/1.11) -> 0 | AH33: 806857
R34: =(Q34-S34)/Q34*100 -> #DIV/0! | AB34: =W34*0.15% -> 0 | AC34: =(S34/1.11) -> 0 | AH34: 807617
R35: =(Q35-S35)/Q35*100 -> #DIV/0! | AB35: =W35*1.5% -> 0 | AC35: =(S35/1.11) -> 0 | AD35: =SUM(AC29:AC35) -> 1.3427838e+09 | AH35: 807617
A36: 46270 | B36: CBPI 11400 | C36: SI-550/2609/37780 | D36: Matthew Aldo Susabda | E36: 13668547 | F36: Indonesia | G36: 1 | I36: 1 | K36: PERFUME | L36: 42504 | M36: PERFUME | N36: =L36 -> 42504 | O36: BVF EP THE IMPERIAL 25 EDT 75ML | P36: 1 | Q36: 2120000 | R36: =(Q36-S36)/Q36*100 -> 0 | S36: =Q36 -> 2120000 | W36: 48820000 | Z36: MDR | AA36: M/MDR 12X | AB36: =W36*5% -> 2441000 | AC36: =(S36/1.11) -> 1909909.9 | AE36: IR | AF36: IR | AG36: IR | AH36: 807567 | AI36: 806422
K37: JEWELRY | L37: 357255 | M37: CL858837 | N37: ARVK60 | O37: CL B01 MINI PG-7.2grs PENDANT | P37: 1 | Q37: 46700000 | R37: =(Q37-S37)/Q37*100 -> 0 | S37: =Q37 -> 46700000 | AB37: =W37*1.3% -> 0 | AC37: =(S37/1.11) -> 42072072 | AH37: 806856
R38: =(Q38-S38)/Q38*100 -> #DIV/0! | AB38: =W38*7% -> 0 | AC38: =(S38/1.11) -> 0 | AH38: 807617
B39: CBPI 11401 | C39: VOID | R39: =(Q39-S39)/Q39*100 -> #DIV/0! | AB39: =W39*1.5% -> 0 | AC39: =(S39/1.11) -> 0
B40: CBPI 11402 | C40: INV-550/2609/02817 | D40: Dhea Zautha | E40: 13669017 | F40: Indonesia | G40: 1 | I40: 1 | K40: WATCHES | L40: 103740 | M40: RE00020 | N40: BUBVZ73 | O40: W GG41 HMSD STE GRE STE AUT *LEAFLET & BOX OCTO ROMA | P40: 1 | Q40: 152300000 | R40: =(Q40-S40)/Q40*100 -> 0 | S40: =Q40 -> 152300000 | V40: =S40 -> 152300000 | Y40: BCA | AB40: =W40*1.5% -> 0 | AC40: =(S40/1.11) -> 1.3720721e+08 | AE40: SK | AF40: SK | AG40: SK | AH40: 804190 | AI40: 806422 | AJ40: EXCHANGE 3 DAYS
...

Sheet SC
A1: =DS!A1 -> BVLGARI – Plaza Indonesia
A2: Service Center Transaction Report
A3: Periode | B3: =DS!B3 -> 46266
A5: Date | B5: CB No. | C5: Repair Bill No | D5: Sales Invoice No | E5: Customer Name | F5: Cosmo CRM ID | G5: Nationality | H5: New | I5: Old | J5: W | K5: F | L5: Category | M5: SAP Code | N5: Item Name | O5: Serial No | P5: Description | Q5: Qty | R5: Gross Sales | S5: Disc. % | T5: Net Sales | U5: Payment | AC5: Achievement | AD5: Daily Total Achievement | AE5: Served By | AF5: CA | AG5: Entitle | AH5: After Sales Support | AI5: DWA | AJ5: Discount Given Reason | AK5: Other Remarks
U6: Deposit CB No | V6: Rp. | W6: Card | X6: OR No. | Y6: Bank Transfer To | Z6: EDC | AA6: Card Type | AB6: Card Commission
A7: 46266 | B7: NO REPAIR | S7: =(R7-T7)/R7*100 -> #DIV/0! | AB7: =W7*1.4% -> 0 | AC7: =(T7/1.11) -> 0 | AD7: =SUM(AC7) -> 0
A8: 46267 | B8: CBPI 11386 | D8: SI-550/2609/37751 | E8: Susana Tatang | F8: 13669871 | G8: Indonesia | N8: DEPOSIT | P8: Deposit 50% RBPI 8094620 | S8: =(R8-T8)/R8*100 -> #DIV/0! | V8: 1200000 | Y8: BCA | AB8: =W8*1.3% -> 0 | AC8: =(T8/1.11) -> 0 | AE8: JJ | AF8: JJ
B9: CBPI 11387 | D9: SI-550/2609/37752 | E9: Felix Kuosanto | F9: 13669875 | G9: Indonesia | N9: DEPOSIT | P9: Deposit FULL PAYMENT RBPI 8094615 | S9: =(R9-T9)/R9*100 -> #DIV/0! | V9: 2400000 | Y9: BCA | AB9: =W9*1.4% -> 0 | AC9: =(T9/1.11) -> 0 | AE9: AJ | AF9: AJ
B10: CBPI 11388 | C10: 8094609 | D10: INV-RBPI/2609/02801 | E10: Ratna Tedja | F10: 13654905 | G10: Indonesia | I10: 1 | K10: 1 | L10: WATCHES | M10: 0 | N10: BB 26 SG | O10: L419712 | P10: Complete Service | Q10: 1 | R10: 7300000 | S10: =(R10-T10)/R10*100 -> 0 | T10: 7300000 | U10: CBPI 11346 | W10: 3650000 | Z10: BCA | AA10: V/BCA | AB10: =W10*1.3% -> 47450 | AC10: =(T10/1.11) -> 6576576.6 | AE10: JJ | AF10: JJ | AG10: JJ | AH10: 806855 | AK10: SI-PI/2609/37755 (Sales Support)
S11: =(R11-T11)/R11*100 -> #DIV/0! | AB11: =W11*1.4% -> 0 | AC11: =(T11/1.11) -> 0 | AH11: 807616
B12: CBPI 11390 | C12: 8094614 | D12: INV-RBPI/2609/02804 | E12: Jhon Levis | F12: 13367243 | G12: Indonesia | I12: 1 | K12: 1 | L12: JEWELRY | M12: 344492 | N12: CL BB | O12: APN000 | P12: Oth COS (Extend Chain) | Q12: 1 | R12: 6200000 | S12: =(R12-T12)/R12*100 -> 0 | T12: 6200000 | U12: CBPI 11343 | AB12: =W12*1.4% -> 0 | AC12: =(T12/1.11) -> 5585585.6 | AD12: =SUM(AC8:AC12) -> 12162162 | AE12: DP | AF12: DP | AG12: DP
A13: 46268 | B13: CBPI 11391 | D13: INV-PI/2609/02805 | E13: Eddy Kurniawan | F13: 13447191 | G13: Indonesia | I13: 1 | K13: 1 | L13: AFSS | M13: 100189572 | N13: 100189572 | O13: 100189572 | P13: KIT-POUCH BRA GG41 CAO-ACI BLU CDP S.S I | Q13: 1 | R13: 5800000 | S13: =(R13-T13)/R13*100 -> 0 | T13: =R13 -> 5800000 | U13: CBPI 11032 | AB13: =W13*2.2% -> 0 | AC13: =(T13/1.11) -> 5225225.2 | AE13: JJ | AF13: JJ | AG13: JJ | AH13: 807617 | AK13: INV-PI/2609/02805 (Sales Support)
S14: =(R14-T14)/R14*100 -> #DIV/0! | AB14: =W14*1.5% -> 0 | AC14: =(T14/1.11) -> 0 | AH14: 807616
S15: =(R15-T15)/R15*100 -> #DIV/0! | AB15: =W15*1.4% -> 0 | AC15: =(T15/1.11) -> 0 | AD15: =SUM(AC13:AC15) -> 5225225.2 | AH15: 806855
A16: 46269 | B16: NO REPAIR | S16: =(R16-T16)/R16*100 -> #DIV/0! | AB16: =W16*1.4% -> 0 | AC16: =(T16/1.11) -> 0
A17: 46270 | B17: CBPI 11399 | D17: SI-RBPI/2609/37774 | E17: Radityo Wibowo | F17: 13626668 | N17: DEPOSIT | P17: Deposit Full Payment RBPI 8094606 | S17: =(R17-T17)/R17*100 -> #DIV/0! | V17: 1200000 | Y17: BCA | AB17: =W17*1.4% -> 0 | AC17: =(T17/1.11) -> 0 | AE17: AL | AF17: AL
B18: FOC | C18: 8094618 | D18: SI-RBPI/2609/37775 | E18: Cindy Chandriani | F18: 13632600 | G18: Indonesia | I18: 1 | K18: 1 | L18: JEWELRY | M18: 360338 | O18: AM4383 | P18: Oth COS (Engrave) | S18: =(R18-T18)/R18*100 -> #DIV/0! | AB18: =W18*0.15% -> 0 | AC18: =(T18/1.11) -> 0 | AE18: AL | AF18: AL | AG18: AL
B19: FOC | C19: 8094619 | D19: SI-RBPI/2609/37776 | E19: Cindy Chandriani | F19: 13632600 | G19: Indonesia | I19: 1 | K19: 1 | L19: JEWELRY | M19: 360362 | O19: W51AYL | P19: Oth COS (Engrave) | S19: =(R19-T19)/R19*100 -> #DIV/0! | AB19: =W19*2.25% -> 0 | AC19: =(T19/1.11) -> 0 | AE19: AL | AF19: AL | AG19: AL
S20: =(R20-T20)/R20*100 -> #DIV/0! | AB20: =W20*2.25% -> 0 | AC20: =(T20/1.11) -> 0
B21: CBPI 11404 | C21: 8094576 | D21: INV-RBPI/2609/02818 | E21: Rizky Pulungan | F21: 13521092 | G21: Indonesia | I21: 1 | K21: 1 | L21: WATCHES | M21: 101353 | N21: BB26WSSD/N | O21: O4633 | P21: Complete Service | Q21: 1 | R21: 7300000 | S21: =(R21-T21)/R21*100 -> 0 | T21: =R21 -> 7300000 | U21: CBPI 11315 | W21: 3650000 | Z21: BCA | AA21: M/CIMB | AB21: =W21*1.3% -> 47450 | AC21: =(T21/1.11) -> 6576576.6 | AE21: AJ | AF21: AJ | AG21: AJ | AH21: 807616 | AK21: SI-PI/2609/37782 (Sales Support)
S22: =(R22-T22)/R22*100 -> #DIV/0! | AB22: =W22*1.5% -> 0 | AC22: =(T22/1.11) -> 0 | AH22: 807617
S23: =(R23-T23)/R23*100 -> #DIV/0! | AB23: =W23*0.15% -> 0 | AC23: =(T23/1.11) -> 0 | AD23: =SUM(AC17:AC23) -> 6576576.6 | AH23: 806855
A24: 46271 | B24: FOC | C24: 8094622 | D24: SI-RBPI/2609/37786 | E24: Sandredee Siwalette | F24: 13251950 | G24: Indonesia | I24: 1 | K24: 1 | L24: WATCHES | M24: 103471 | N24: RE00082 | O24: BUB64BG | P24: Basic Service (Purchase Warranty) | S24: =(R24-T24)/R24*100 -> #DIV/0! | AB24: =W24*0.15% -> 0 | AC24: =(T24/1.11) -> 0 | AD24: =SUM(AC24) -> 0 | AE24: DP | AF24: DP | AG24: DP | AH24: 806855 | AK24: SI-PI/2609/37787 (Sales Support)
A25: 46272 | B25: CBPI 11413 | D25: SI-RBPI/2609/37792 | E25: Cially Than | F25: 13209277 | N25: DEPOSIT | P25: DEPOSIT FULL PAYMENT RBPI 8094634 | S25: =(R25-T25)/R25*100 -> #DIV/0! | V25: 3500000 | Y25: BCA | AB25: =W25*1.4% -> 0 | AC25: =(T25/1.11) -> 0 | AE25: DP | AF25: DP | AH25: 807616
B26: CBPI 11414 | D26: INV-PI/2609/02826 | E26: Lely Natali | F26: 13675397 | G26: Indonesia | I26: 1 | K26: 1 | L26: AFSS | M26: 100117486 | N26: 100117486 | O26: 100117486 | P26: BRA BZ30 CLF BLK GLS S.M I16.00 B12.00 | Q26: 1 | R26: 4000000 | S26: =(R26-T26)/R26*100 -> 0 | T26: =R26 -> 4000000 | W26: =T26 -> 4000000 | Z26: BCA | AA26: V/UOB | AB26: =W26*1.3% -> 52000 | AC26: =(T26/1.11) -> 3603603.6 | AE26: AJ | AF26: DP | AG26: DP
B27: CBPI 11417 | D27: SI-RBPI/2609/37797 | E27: Alexandra Askandar | F27: 13481737 | N27: DEPOSIT | P27: DEPOSIT 50% RBPI 8094590 | S27: =(R27-T27)/R27*100 -> #DIV/0! | V27: 1200000 | Z27: MDR | AB27: =W27*1.5% -> 0 | AC27: =(T27/1.11) -> 0 | AD27: =SUM(AC25:AC27) -> 3603603.6 | AE27: IR | AF27: IR
A28: 46273 | B28: CBPI 11420 | C28: 8094627 | D28: INV-RBPI/2609/02830 | E28: Karima Anjani | F28: 13677331 | G28: Indonesia | I28: 1 | K28: 1 | L28: WATCHES | M28: 100264 | N28: BB33WSSD | O28: L9030 | P28: Diagnostic Fee | Q28: 1 | R28: 350000 | S28: =(R28-T28)/R28*100 -> 0 | T28: =R28 -> 350000 | W28: =T28 -> 350000 | Z28: BCA | AA28: V/BCA | AB28: =W28*1.25% -> 4375 | AC28: =(T28/1.11) -> 315315.32
B29: CBPI 11421 | C29: 8094606 | D29: INV-RBPI/2609/02831 | E29: Radityo Wibowo | F29: 13626668 | G29: Indonesia | I29: 1 | K29: 1 | L29: WATCHES | M29: 100233 | N29: BB30 SSD | O29: F32905 | P29: Basic Service | Q29: 1 | R29: 2400000 | S29: =(R29-T29)/R29*100 -> 0 | T29: =R29 -> 2400000 | U29: CBPI 11308, 11399 | AB29: =W29*1.5% -> 0 | AC29: =(T29/1.11) -> 2162162.2 | AE29: AK | AF29: AL | AG29: AL | AH29: 807617 | AK29: SI-PI/2609/37801 (Sales Support)
S30: =(R30-T30)/R30*100 -> #DIV/0! | AB30: =W30*1.3% -> 0 | AC30: =(T30/1.11) -> 0 | AH30: 807616
S31: =(R31-T31)/R31*100 -> #DIV/0! | AB31: =W31*1.5% -> 0 | AC31: =(T31/1.11) -> 0 | AH31: 806855
B32: FOC | C32: 8094632 | D32: SI-RBPI/2609/37802 | E32: Friska Theresia | F32: 13597281 | G32: Indonesia | I32: 1 | K32: 1 | L32: JEWELRY | M32: 358771 | N32: AN859325 | O32: 7LYWCR | P32: Oth COS (Engrave) | S32: =(R32-T32)/R32*100 -> #DIV/0! | AB32: =W32*1.5% -> 0 | AC32: =(T32/1.11) -> 0 | AE32: AK | AF32: AK | AG32: AK
B33: FOC | C33: 8094633 | D33: SI-RBPI/2609/37803 | E33: Friska Theresia | F33: 13597281 | G33: Indonesia | I33: 1 | K33: 1 | L33: JEWELRY | M33: 353268 | N33: AN857896 | O33: ANH353 | P33: Oth COS (Engrave) | S33: =(R33-T33)/R33*100 -> #DIV/0! | AB33: =W33*1.3% -> 0 | AC33: =(T33/1.11) -> 0 | AD33: =SUM(AC28:AC33) -> 2477477.5 | AE33: AK | AF33: AK | AG33: AK
A34: 46274 | B34: CBPI 11425 | D34: SI-RBPI/2609/37815 | E34: Andy Maulana | F34: 13677327 | G34: Indonesia | N34: DEPOSIT | P34: Deposit Full Payment RBPI 8094631 | S34: =(R34-T34)/R34*100 -> #DIV/0! | V34: 3600000 | Y34: BCA | AB34: =W34*1.5% -> 0 | AC34: =(T34/1.11) -> 0 | AD34: =SUM(AC34) -> 0 | AE34: AJ | AF34: AJ
A35: 46275 | B35: CBPI 11430 | C35: 8094601 | D35: INV-RBPI/2609/02839 | E35: Astari Napitupulu | F35: 13629783 | G35: Indonesia | I35: 1 | K35: 1 | L35: WATCHES | M35: 101886 | N35: BBL26WSS/12 | O35: PO4250 | P35: Basic Service | Q35: 1 | R35: 2400000 | S35: =(R35-T35)/R35*100 -> 0 | T35: =R35 -> 2400000 | U35: CBPI 11302 | W35: 1200000 | Z35: BCA | AA35: D/BCA | AB35: =W35*0.15% -> 1800 | AC35: =(T35/1.11) -> 2162162.2 | AE35: IR | AF35: SK | AG35: SK | AH35: 807616 | AK35: SI-PI/2609/37824 (Sales Support)
S36: =(R36-T36)/R36*100 -> #DIV/0! | T36: =R36 -> 0 | AB36: =W36*1.75% -> 0 | AC36: =(T36/1.11) -> 0 | AH36: 806855
S37: =(R37-T37)/R37*100 -> #DIV/0! | AB37: =W37*1.5% -> 0 | AC37: =(T37/1.11) -> 0 | AH37: 807617
A38: 46276 | B38: CBPI 11436 | C38: 8094620 | D38: INV-RBPI/2609/02843 | E38: Susana Tatang | F38: 13669871 | G38: Indonesia | I38: 1 | K38: 1 | L38: WATCHES | M38: 101887 | N38: BBL26WSPG/12 | O38: L5914 | P38: Basic Service | Q38: 1 | R38: 2400000 | S38: =(R38-T38)/R38*100 -> 0 | T38: =R38 -> 2400000 | U38: CBPI 11386 | W38: 1200000 | Z38: CIMBNIAGA | AA38: M//CIMBNIAGA | AB38: =W38*1.75% -> 21000 | AC38: =(T38/1.11) -> 2162162.2 | AE38: SK | AF38: JJ | AG38: JJ | AH38: 807617
S39: =(R39-T39)/R39*100 -> #DIV/0! | AB39: =W39*1.5% -> 0 | AC39: =(T39/1.11) -> 0 | AH39: 806855
S40: =(R40-T40)/R40*100 -> #DIV/0! | AB40: =W40*1.5% -> 0 | AC40: =(T40/1.11) -> 0 | AD40: =SUM(AC35:AC40) -> 4324324.3 | AH40: 807616 | AK40: SI-PI/2609/37833 (Sales Support)
A41: 46277 | B41: CBPI 11439 | C41: 8094566 | D41: INV-RBPI/2609/02848 | E41: Sita Satar | F41: 13570016 | G41: Indonesia | I41: 1 | K41: 1 | L41: WATCHES | M41: 100120 | N41: BB23 | O41: D107031 | P41: Complete Service | Q41: 1 | R41: 7300000 | S41: =(R41-T41)/R41*100 -> 0 | T41: 7300000 | U41: CBPI 11259 | W41: 3650000 | Z41: BCA | AA41: D/BCA | AB41: =W41*0.15% -> 5475 | AC41: =(T41/1.11) -> 6576576.6 | AE41: SK | AF41: SK | AG41: SK | AH41: 807616 | AK41: SI-PI/2609/37834 (Sales Support)
...

Sheet SMI
A1: =DS!A1 -> BVLGARI – Plaza Indonesia
A2: SMI Transaction Report
A3: Periode | B3: =DS!B3 -> 46266
AF4: HARUS DI ISI
A5: Date | B5: CB No. | C5: Sales Invoice No | D5: Customer Name | E5: Cosmo CRM ID | F5: Nationality | G5: New | H5: Old | I5: W | J5: F | K5: Category | L5: SAP Code | M5: Item Name | N5: Serial No | O5: Description | P5: Qty | Q5: Gross Sales | R5: Disc. % | S5: Net Sales | T5: Payment | AB5: Achievement | AC5: Daily Total Achievement | AD5: Served By | AE5: CA | AF5: Entitle | AG5: After Sales Support | AH5: DWA | AI5: SMI Commission | AJ5: Discount Given Reason | AK5: After Sales Support | AL5: Other Remarks
T6: Deposit CB No | U6: Rp. | V6: Card | W6: OR No. | X6: Bank Transfer To | Y6: EDC | Z6: Card Type | AA6: Card Commission
A7: 46269 | B7: CBPI 11396 | C7: INV-PI/2609/02812 | D7: Cially Than | E7: 13209277 | F7: Indonesia | H7: 1 | J7: 1 | K7: JEWELRY | L7: 358349 | M7: CL859268 | N7: 7EA7AP | O7: CL B01 ROCK LONG YG-24.9grs 76PAVE-0.38ct PENDANT | P7: 1 | Q7: 235200000 | R7: =(Q7-S7)/Q7*100 -> 0 | S7: =Q7 -> 235200000 | T7: CBPI 11327 | AA7: =V7*1.7% -> 0 | AB7: =(S7/1.11) -> 2.1189189e+08 | AC7: =(S7/1.11) -> 2.1189189e+08 | AD7: DP | AE7: DP | AF7: DP | AI7: 12000000 | AJ7: SMI | AK7: 807567 | AL7: 80 : 20 (MM & HS)
R8: =(Q8-S8)/Q8*100 -> #DIV/0! | AA8: =V8*1.7% -> 0 | AB8: =(S8/1.11) -> 0 | AK8: 807617
R9: =(Q9-S9)/Q9*100 -> #DIV/0! | AA9: =V9*1.5% -> 0 | AB9: =(S9/1.11) -> 0 | AK9: 806856
R10: =(Q10-S10)/Q10*100 -> #DIV/0! | AA10: =V10*1.3% -> 0 | AB10: =(S10/1.11) -> 0 | AK10: 806422
R11: =(Q11-S11)/Q11*100 -> #DIV/0! | AA11: =V11*1.5% -> 0 | AB11: =(S11/1.11) -> 0
R12: =(Q12-S12)/Q12*100 -> #DIV/0! | AA12: =V12*1.5% -> 0 | AB12: =(S12/1.11) -> 0
R13: =(Q13-S13)/Q13*100 -> #DIV/0! | AA13: =V13*1.5% -> 0 | AB13: =(S13/1.11) -> 0
R14: =(Q14-S14)/Q14*100 -> #DIV/0! | AA14: =V14*0.15% -> 0 | AB14: =(S14/1.11) -> 0
R15: =(Q15-S15)/Q15*100 -> #DIV/0! | AA15: =V15*1.5% -> 0 | AB15: =(S15/1.11) -> 0
R16: =(Q16-S16)/Q16*100 -> #DIV/0! | AA16: =V16*1.5% -> 0 | AB16: =(S16/1.11) -> 0
R17: =(Q17-S17)/Q17*100 -> #DIV/0! | AA17: =V17*1.5% -> 0 | AB17: =(S17/1.11) -> 0
R18: =(Q18-S18)/Q18*100 -> #DIV/0! | AA18: =V18*1.5% -> 0 | AB18: =(S18/1.11) -> 0
R19: =(Q19-S19)/Q19*100 -> #DIV/0! | AA19: =V19*1.5% -> 0 | AB19: =(S19/1.11) -> 0
R20: =(Q20-S20)/Q20*100 -> #DIV/0! | AA20: =V20*1.5% -> 0 | AB20: =(S20/1.11) -> 0
R21: =(Q21-S21)/Q21*100 -> #DIV/0! | AA21: =V21*1.5% -> 0 | AB21: =(S21/1.11) -> 0
R22: =(Q22-S22)/Q22*100 -> #DIV/0! | AA22: =V22*1.5% -> 0 | AB22: =(S22/1.11) -> 0
R23: =(Q23-S23)/Q23*100 -> #DIV/0! | AA23: =V23*1.5% -> 0 | AB23: =(S23/1.11) -> 0
R24: =(Q24-S24)/Q24*100 -> #DIV/0! | AA24: =V24*1.5% -> 0 | AB24: =(S24/1.11) -> 0
R25: =(Q25-S25)/Q25*100 -> #DIV/0! | AA25: =V25*1.5% -> 0 | AB25: =(S25/1.11) -> 0
R26: =(Q26-S26)/Q26*100 -> #DIV/0! | AA26: =V26*1.5% -> 0 | AB26: =(S26/1.11) -> 0
... R43: =(Q43-S43)/Q43*100 -> #DIV/0! | AA43: =V43*1.5% -> 0 | AB43: =(S43/1.11) -> 0
D44: TOTAL | G44: =SUM(G7:G43) -> 0 | H44: =SUM(H7:H43) -> 1 | I44: =SUM(I7:I43) -> 0 | J44: =SUM(J7:J43) -> 1 | P44: =SUM(P7:P43) -> 1 | Q44: =SUM(Q7:Q43) -> 235200000 | S44: =SUM(S7:S43) -> 235200000 | U44: =SUM(U7:U43) -> 0 | V44: =SUM(V7:V43) -> 0 | AA44: =SUM(AA7:AA43) -> 0 | AB44: =SUM(AB7:AB43) -> 2.1189189e+08 | AC44: =SUM(AC7:AC43) -> 2.1189189e+08
AB46: Store:
AB47: SMI: | AC47: =AB44 -> 2.1189189e+08
AB48: TOTAL: | AC48: =AC46+AC47 -> 2.1189189e+08
AB50: kurang sales: -
AC52: TOTAL ACHIEVEMENT
AC53: =AC48/AC59*100% -> 0.015695696
AB57: Target Store:: | AC57: =DS!AD322 -> 13500000000
AB58: Target SMI: | AC58: 0
AB59: Total Target: | AC59: =AC57 -> 13500000000

Sheet HO
A1: =DS!A1 -> BVLGARI – Plaza Indonesia
A2: Head Office Transaction Report
A3: Periode | B3: =DS!B3 -> 46266
A5: Date | B5: AB No. | C5: Sales Invoice No | D5: Customer Name | E5: Cosmo CRM ID | F5: Nationality | G5: New | H5: Old | I5: W | J5: F | K5: Category | L5: SAP Code | M5: Item Name | N5: Serial No | O5: Description | P5: Qty | Q5: Gross Sales | R5: Disc. % | S5: Net Sales | T5: Payment | AB5: Achievement | AC5: Daily Total Achievement | AD5: CA | AE5: After Sales Support | AF5: DWA | AG5: Other Remarks
T6: Deposit CB No | U6: Rp. | V6: Card | W6: OR No. | X6: Bank Transfer To | Y6: EDC | Z6: Card Type | AA6: Card Commission
R7: =(Q7-S7)/Q7*100 -> #DIV/0! | AB7: =(S7/1.11) -> 0
R8: =(Q8-S8)/Q8*100 -> #DIV/0! | AB8: =(S8/1.11) -> 0
R9: =(Q9-S9)/Q9*100 -> #DIV/0! | AB9: =(S9/1.11) -> 0
R10: =(Q10-S10)/Q10*100 -> #DIV/0! | AB10: =(S10/1.11) -> 0
R11: =(Q11-S11)/Q11*100 -> #DIV/0! | AB11: =(S11/1.11) -> 0
R12: =(Q12-S12)/Q12*100 -> #DIV/0! | AB12: =(S12/1.11) -> 0
R13: =(Q13-S13)/Q13*100 -> #DIV/0! | AB13: 0
R14: =(Q14-S14)/Q14*100 -> #DIV/0! | AB14: =(S14/1.11) -> 0
R15: =(Q15-S15)/Q15*100 -> #DIV/0! | AB15: =(S15/1.11) -> 0
R16: =(Q16-S16)/Q16*100 -> #DIV/0! | AB16: =(S16/1.11) -> 0
R17: =(Q17-S17)/Q17*100 -> #DIV/0! | AB17: =(S17/1.11) -> 0
R18: =(Q18-S18)/Q18*100 -> #DIV/0! | AB18: =(S18/1.11) -> 0
R19: =(Q19-S19)/Q19*100 -> #DIV/0! | AB19: =(S19/1.11) -> 0
R20: =(Q20-S20)/Q20*100 -> #DIV/0! | AB20: =(S20/1.11) -> 0
R21: =(Q21-S21)/Q21*100 -> #DIV/0! | AB21: =(S21/1.11) -> 0
R22: =(Q22-S22)/Q22*100 -> #DIV/0! | AB22: =(S22/1.11) -> 0
R23: =(Q23-S23)/Q23*100 -> #DIV/0! | AB23: =(S23/1.11) -> 0
R24: =(Q24-S24)/Q24*100 -> #DIV/0! | AB24: =(S24/1.11) -> 0
R25: =(Q25-S25)/Q25*100 -> #DIV/0! | AB25: =(S25/1.11) -> 0
... R32: =(Q32-S32)/Q32*100 -> #DIV/0! | AB32: =(S32/1.11) -> 0
D33: TOTAL | G33: =SUM(G7:G32) -> 0 | H33: =SUM(H7:H32) -> 0 | I33: =SUM(I7:I32) -> 0 | J33: =SUM(J7:J32) -> 0 | P33: =SUM(P7:P32) -> 0 | Q33: =SUM(Q7:Q32) -> 0 | S33: =SUM(S7:S32) -> 0 | U33: =SUM(U7:U32) -> 0 | V33: =SUM(V7:V32) -> 0 | AA33: =SUM(AA7:AA32) -> 0 | AB33: =SUM(AB7:AB32) -> 0 | AC33: =SUM(AC7:AC32) -> 0
AB35: Store:
AB36: SMI: | AC36: =SMI!AB44 -> 2.1189189e+08
AB37: TOTAL: | AC37: =AC35+AC36 -> 2.1189189e+08
AB39: kurang sales: -
AC41: TOTAL ACHIEVEMENT
AC42: =AC37/AC48*100% -> 0.015695696
AB46: Target Store:: | AC46: =DS!AD322 -> 13500000000
AB47: Target SMI: | AC47: 0
AB48: Total Target: | AC48: =AC46 -> 13500000000

Sheet MARKOM
A1: =DS!A1 -> BVLGARI – Plaza Indonesia
A2: Markom Transaction Report
A3: Periode | B3: =DS!B3 -> 46266 | C3: Markom tidak di hitung traffic, tidak ada achv individual, store, hanya ada komisi jika ada voucher nya
A5: Date | B5: CB No. | C5: Issue Receipt No. | D5: Customer Name | E5: Cosmo CRM ID | F5: Nationality | G5: New | H5: Old | I5: W | J5: F | K5: Category | L5: SAP Code | M5: Item Name | N5: Serial No | O5: Description | P5: Qty | Q5: Gross Sales | R5: Disc. % | S5: Net Sales | T5: Payment | AC5: Achievement | AD5: Daily Total Achievement | AE5: Served By | AF5: CA | AG5: Entitle | AH5: After Sales Support | AI5: DWA | AJ5: Spot Incentive | AK5: Other Remarks
T6: Deposit CB No | U6: Rp. | V6: Card | W6: GV No. | X6: Tanda Terima | Y6: Bank Transfer To | Z6: EDC | AA6: Card Type | AB6: Card Commission
R7: =(Q7-S7)/Q7*100 -> #DIV/0! | AB7: =V7*1.5% -> 0 | AC7: =(S7/1.11) -> 0
R8: =(Q8-S8)/Q8*100 -> #DIV/0! | AB8: =V8*1.5% -> 0 | AC8: =(S8/1.11) -> 0
R9: =(Q9-S9)/Q9*100 -> #DIV/0! | AB9: =V9*1.5% -> 0 | AC9: =(S9/1.11) -> 0
R10: =(Q10-S10)/Q10*100 -> #DIV/0! | AB10: =V10*1.3% -> 0 | AC10: =(S10/1.11) -> 0
R11: =(Q11-S11)/Q11*100 -> #DIV/0! | AB11: =V11*1.5% -> 0 | AC11: =(S11/1.11) -> 0
R12: =(Q12-S12)/Q12*100 -> #DIV/0! | AB12: =V12*1.5% -> 0 | AC12: =(S12/1.11) -> 0
R13: =(Q13-S13)/Q13*100 -> #DIV/0! | AB13: =V13*1.5% -> 0 | AC13: =(S13/1.11) -> 0
R14: =(Q14-S14)/Q14*100 -> #DIV/0! | AB14: =V14*1.5% -> 0 | AC14: =(S14/1.11) -> 0
R15: =(Q15-S15)/Q15*100 -> #DIV/0! | AB15: =V15*1.5% -> 0 | AC15: =(S15/1.11) -> 0
R16: =(Q16-S16)/Q16*100 -> #DIV/0! | AB16: =V16*1.5% -> 0 | AC16: =(S16/1.11) -> 0
R17: =(Q17-S17)/Q17*100 -> #DIV/0! | AB17: =V17*1.5% -> 0 | AC17: =(S17/1.11) -> 0
R18: =(Q18-S18)/Q18*100 -> #DIV/0! | AB18: =V18*1.5% -> 0 | AC18: =(S18/1.11) -> 0
R19: =(Q19-S19)/Q19*100 -> #DIV/0! | AB19: =V19*1.5% -> 0 | AC19: =(S19/1.11) -> 0
R20: =(Q20-S20)/Q20*100 -> #DIV/0! | AB20: =V20*1.5% -> 0 | AC20: =(S20/1.11) -> 0
R21: =(Q21-S21)/Q21*100 -> #DIV/0! | AB21: =V21*1.5% -> 0 | AC21: =(S21/1.11) -> 0
D22: TOTAL | G22: =SUM(G7:G21) -> 0 | H22: =SUM(H7:H21) -> 0 | I22: =SUM(I7:I21) -> 0 | J22: =SUM(J7:J21) -> 0 | P22: =SUM(P7:P21) -> 0 | Q22: =SUM(Q7:Q21) -> 0 | S22: =SUM(S7:S21) -> 0 | U22: =SUM(U7:U21) -> 0 | V22: =SUM(V7:V21) -> 0 | AB22: =SUM(AB7:AB21) -> 0 | AC22: =SUM(AC7:AC21) -> 0 | AD22: =SUM(AD7:AD21) -> 0 | AJ22: TOTAL
AC24: Store:
AC25: SMI: | AD25: =SMI!AB44 -> 2.1189189e+08
AC26: TOTAL: | AD26: =AD24+AD25 -> 2.1189189e+08
AC28: kurang sales: -
AD30: TOTAL ACHIEVEMENT
AD31: =AD26/AD37*100% -> 0.015695696
AC35: Target Store:: | AD35: =DS!AD322 -> 13500000000
AC36: Target SMI: | AD36: 0
AC37: Total Target: | AD37: =AD35 -> 13500000000

Sheet IN AND OUT
A1: =DS!A1 -> BVLGARI – Plaza Indonesia
A2: Daily Sales Transaction IN AND OUT Report
A3: Periode | B3: =DS!B3 -> 46266
A6: IN | AG6: HARUS DI ISI
A7: Date | B7: CB No. | C7: Sales Invoice No | D7: Customer Name | E7: Cosmo CRM ID | F7: Nationality | G7: New | H7: Old | I7: W | J7: F | K7: Category | L7: SAP Code | M7: Item Name | N7: Serial No | O7: Description | P7: Qty | Q7: Gross Sales | R7: Disc. % | S7: Net Sales | T7: Discount Given Reason | U7: Payment | AC7: Achievement | AD7: Daily Total Achievement | AE7: Served By | AF7: CA | AG7: Entitle | AH7: Other Remarks
U8: Deposit CB No | V8: Rp. | W8: Card | X8: OR No. | Y8: Bank Transfer To | Z8: EDC | AA8: Card Type | AB8: Card Commission
R9: =(Q9-S9)/Q9*100 -> #DIV/0! | AB9: =W9*0.15% -> 0 | AC9: =(S9/1.11) -> 0
R10: =(Q10-S10)/Q10*100 -> #DIV/0! | AB10: =W10*1.5% -> 0 | AC10: =(S10/1.11) -> 0
R11: =(Q11-S11)/Q11*100 -> #DIV/0! | AB11: =W11*1.5% -> 0 | AC11: =(S11/1.11) -> 0
R12: =(Q12-S12)/Q12*100 -> #DIV/0! | AB12: =W12*1.3% -> 0 | AC12: =(S12/1.11) -> 0
R13: =(Q13-S13)/Q13*100 -> #DIV/0! | AB13: =W13*1.3% -> 0 | AC13: =(S13/1.11) -> 0
R14: =(Q14-S14)/Q14*100 -> #DIV/0! | AB14: =W14*1.3% -> 0 | AC14: =(S14/1.11) -> 0
R15: =(Q15-S15)/Q15*100 -> #DIV/0! | AB15: =W15*1.3% -> 0 | AC15: =(S15/1.11) -> 0
R16: =(Q16-S16)/Q16*100 -> #DIV/0! | AB16: =W16*1.3% -> 0 | AC16: =(S16/1.11) -> 0
R17: =(Q17-S17)/Q17*100 -> #DIV/0! | AB17: =W17*1.3% -> 0 | AC17: =(S17/1.11) -> 0
R18: =(Q18-S18)/Q18*100 -> #DIV/0! | AB18: =W18*1.3% -> 0 | AC18: =(S18/1.11) -> 0
R19: =(Q19-S19)/Q19*100 -> #DIV/0! | AB19: =W19*1.3% -> 0 | AC19: =(S19/1.11) -> 0
R20: =(Q20-S20)/Q20*100 -> #DIV/0! | AB20: =W20*1.3% -> 0 | AC20: =(S20/1.11) -> 0
R21: =(Q21-S21)/Q21*100 -> #DIV/0! | AB21: =W21*1.3% -> 0 | AC21: =(S21/1.11) -> 0
R22: =(Q22-S22)/Q22*100 -> #DIV/0! | AB22: =W22*1.3% -> 0 | AC22: =(S22/1.11) -> 0
R23: =(Q23-S23)/Q23*100 -> #DIV/0! | AB23: =W23*1.9% -> 0 | AC23: =(S23/1.11) -> 0
R24: =(Q24-S24)/Q24*100 -> #DIV/0! | AB24: =W24*1.3% -> 0 | AC24: =(S24/1.11) -> 0
R25: =(Q25-S25)/Q25*100 -> #DIV/0! | AB25: =W25*1.3% -> 0 | AC25: =(S25/1.11) -> 0
R26: =(Q26-S26)/Q26*100 -> #DIV/0! | AB26: =W26*1.9% -> 0 | AC26: =(S26/1.11) -> 0
R27: =(Q27-S27)/Q27*100 -> #DIV/0! | AB27: =W27*1.3% -> 0 | AC27: =(S27/1.11) -> 0
D28: TOTAL | G28: =SUM(G9:G27) -> 0 | H28: =SUM(H9:H27) -> 0 | I28: =SUM(I9:I27) -> 0 | J28: =SUM(J9:J27) -> 0 | P28: =SUM(P9:P27) -> 0 | Q28: =SUM(Q9:Q27) -> 0 | S28: =SUM(S9:S27) -> 0 | V28: =SUM(V9:V27) -> 0 | W28: =SUM(W9:W27) -> 0 | AB28: =SUM(AB9:AB27) -> 0 | AC28: =SUM(AC9:AC27) -> 0 | AD28: =SUM(AD9:AD27) -> 0
A30: OUT
A31: Date | B31: CB No. | C31: Sales Invoice No | D31: Customer Name | E31: Cosmo CRM ID | F31: Nationality | G31: New | H31: Old | I31: W | J31: F | K31: Category | L31: SAP Code | M31: Item Name | N31: Serial No | O31: Description | P31: Qty | Q31: Gross Sales | R31: Disc. % | S31: Net Sales | T31: Discount Given Reason | U31: Payment | AC31: Achievement | AD31: Daily Total Achievement | AE31: Served By | AF31: CA | AG31: Entitle | AH31: DWA | AI31: Other Remarks
U32: Deposit CB No | V32: Rp. | W32: Card | X32: OR No. | Y32: Bank Transfer To | Z32: EDC | AA32: Card Type | AB32: Card Commission
R33: =(Q33-S33)/Q33*100 -> #DIV/0! | AB33: =W33*0.15% -> 0 | AC33: =(S33/1.11) -> 0
R34: =(Q34-S34)/Q34*100 -> #DIV/0! | AB34: =W34*1.4% -> 0 | AC34: =(S34/1.11) -> 0
R35: =(Q35-S35)/Q35*100 -> #DIV/0! | AB35: =W35*1.25% -> 0 | AC35: =(S35/1.11) -> 0
R36: =(Q36-S36)/Q36*100 -> #DIV/0! | AB36: =W36*1.5% -> 0 | AC36: =(S36/1.11) -> 0
R37: =(Q37-S37)/Q37*100 -> #DIV/0! | AB37: =W37*1.5% -> 0 | AC37: =(S37/1.11) -> 0
R38: =(Q38-S38)/Q38*100 -> #DIV/0! | AB38: =W38*1.3% -> 0 | AC38: =(S38/1.11) -> 0
R39: =(Q39-S39)/Q39*100 -> #DIV/0! | AB39: =W39*1.5% -> 0 | AC39: =(S39/1.11) -> 0
R40: =(Q40-S40)/Q40*100 -> #DIV/0! | AB40: =W40*1.5% -> 0 | AC40: =(S40/1.11) -> 0
R41: =(Q41-S41)/Q41*100 -> #DIV/0! | AB41: =W41*1.5% -> 0 | AC41: =(S41/1.11) -> 0
R42: =(Q42-S42)/Q42*100 -> #DIV/0! | AB42: =W42*1.5% -> 0 | AC42: =(S42/1.11) -> 0
R43: =(Q43-S43)/Q43*100 -> #DIV/0! | AB43: =W43*1.5% -> 0 | AC43: =(S43/1.11) -> 0
...

Sheet TRAFFIC & COMMISSION REPORT
A1: BVLGARI – PLAZA INDONESIA
A2: Traffic & Individual Commission Report
A3: =DS!B3 -> 46266
A5: RUMUS: | E5: Watches Specialist khusus penjualan Jam tangan
A6: DISC | B6: Peritem | C6: SHJ / LLG / OCTO | E6: DISC | F6: Others 1-2pc | G6: Others >3pc | H6: OCTO 1-2pc | I6: OCTO >3pc | K6: JEWEL 25 JUTA
A7: 0 | B7: 0.03 | C7: 0.036 | E7: 0 | F7: 0.033 | G7: 0.036 | H7: 0.0396 | I7: 0.036 | K7: WATCH 50 JUTA
A8: 1-10% | B8: 0.012 | C8: 0.024 | E8: 1-10% | F8: 0.0132 | G8: 0.0144 | H8: 0.022 | I8: 0.024 | K8: ACC 6 JUTA
A9: 11-15% | B9: 0.006 | C9: 0.012 | E9: 11-15% | F9: 0.0066 | G9: 0.0072 | H9: 0.011 | I9: 0.012
A10: >16% | B10: 0 | C10: 0.005 | E10: >16% | F10: 0 | G10: 0 | H10: 0.0055 | I10: 0.006
A12: Store Achievment | B12: Manager | C12: SPV
W14: Taret individual di bagi jumlah CA
BB16: 0.035 | BC16: 0.03 | BD16: 0.025 | BE16: 0.02 | BF16: 0.0175 | BG16: 0.01 | BH16: 0.007 | BI16: 0.005 | BJ16: 0.0035
H18: 3 | I18: 2.5 | J18: 2 | K18: 1 | L18: Target Butik | S18: 3 | T18: 2.5 | U18: 2 | V18: 1 | AF18: 3 | AG18: 2.5 | AH18: 2 | AI18: 1 | AQ18: 3 | AR18: 2.5 | AS18: 2 | AT18: 1 | BQ18: 3 | BR18: 2.5 | BS18: 2 | BT18: 1 | CB18: 3 | CC18: 2.5 | CD18: 2 | CE18: 1 | CM18: 3 | CN18: 2.5 | CO18: 2 | CP18: 1 | CX18: 3 | CY18: 2.5 | CZ18: 2 | DA18: 1 | DI18: 3 | DJ18: 2.5 | DK18: 2 | DL18: 1 | DT18: 3 | DU18: 2.5 | DV18: 2 | DW18: 1 | EE18: 3 | EF18: 2.5 | EG18: 2 | EH18: 1 | EP18: 3 | EQ18: 2.5 | ER18: 2 | ES18: 1 | FA18: 3 | FB18: 2.5 | FC18: 2 | FD18: 1 | FL18: 3 | FM18: 2.5 | FN18: 2 | FO18: 1
A19: BULAN | B19: MONIQ | L19: =DS!AD322 -> 13500000000 | M19: HERDY | W19: 1050000000 | X19: AJENG | AD19: Watches Specialist | AJ19: 1556250000 | AK19: SYANDY | AU19: =AJ19 -> 1556250000 | AV19: SISKA (VIP CA) | BJ19: =AJ19 -> 1556250000 | BK19: DIAN | BU19: =AJ19 -> 1556250000 | BV19: IRMA | CF19: =AJ19 -> 1556250000 | CG19: JOJO | CQ19: =AJ19 -> 1556250000 | CR19: ARI | DB19: =AJ19 -> 1556250000 | DC19: ALVIN | DM19: =AJ19 -> 1556250000 | DN19: ARIF PS | FQ19: TOTAL
B20: DAILY TRAFFIC | C20: TRAFFIC W/DATA | D20: QTY | E20: GROSS | F20: NETT | G20: After Tax & CC | H20: 0.036 | I20: 0.03 | J20: 0.024 | K20: 0.012 | L20: 0.006 | M20: DAILY TRAFFIC | N20: TRAFFIC W/DATA | O20: QTY | P20: GROSS | Q20: NETT | R20: After Tax & CC | S20: 0.036 | T20: 0.03 | U20: 0.024 | V20: 0.012 | W20: 0.006 | X20: DAILY TRAFFIC | Y20: TRAFFIC W/DATA | Z20: QTY | AA20: GROSS | AB20: NETT | AC20: After Tax & CC | AD20: 1-2pc | AE20: >3pc | AF20: 0.036 | AG20: 0.03 | AH20: 0.024 | AI20: 0.012 | AJ20: 0.006 | AK20: DAILY TRAFFIC | AL20: TRAFFIC W/DATA | AM20: QTY | AN20: GROSS | AO20: NETT | AP20: After Tax & CC | AQ20: 0.036 | AR20: 0.03 | AS20: 0.024 | AT20: 0.012 | AU20: 0.006 | AV20: DAILY TRAFFIC | AW20: TRAFFIC W/DATA | AX20: QTY | AY20: GROSS | AZ20: NETT | BA20: After Tax & CC | BB20: 0.042 | BC20: 0.036 | BD20: 0.03 | BE20: 0.024 | BF20: 0.021 | BG20: 0.012 | BH20: 0.0083 | BI20: 0.006 | BJ20: 0.0042 | BK20: DAILY TRAFFIC | BL20: TRAFFIC W/DATA | BM20: QTY | BN20: GROSS | BO20: NETT | BP20: After Tax & CC | BQ20: 0.036 | BR20: 0.03 | BS20: 0.024 | BT20: 0.012 | BU20: 0.006 | BV20: DAILY TRAFFIC | BW20: TRAFFIC W/DATA | BX20: QTY | BY20: GROSS | BZ20: NETT | CA20: After Tax & CC | CB20: 0.036 | CC20: 0.03 | CD20: 0.024 | CE20: 0.012 | CF20: 0.006 | CG20: DAILY TRAFFIC | CH20: TRAFFIC W/DATA | CI20: QTY | CJ20: GROSS | CK20: NETT | CL20: After Tax & CC | CM20: 0.036 | CN20: 0.03 | CO20: 0.024 | CP20: 0.012 | CQ20: 0.006 | CR20: DAILY TRAFFIC | CS20: TRAFFIC W/DATA | CT20: QTY | CU20: GROSS | CV20: NETT | CW20: After Tax & CC | CX20: 0.036 | CY20: 0.03 | CZ20: 0.024 | DA20: 0.012 | DB20: 0.006 | DC20: DAILY TRAFFIC | DD20: TRAFFIC W/DATA | DE20: QTY | DF20: GROSS | DG20: NETT | DH20: After Tax & CC | DI20: 0.036 | DJ20: 0.03 | DK20: 0.024 | DL20: 0.012 | DM20: 0.006 | DN20: DAILY TRAFFIC | DO20: TRAFFIC W/DATA | DP20: QTY | DQ20: GROSS | DR20: NETT | DS20: After Tax & CC | DT20: 0.036 | DU20: 0.03 | DV20: 0.024 | DW20: 0.012 | DX20: 0.006 | DY20: DAILY TRAFFIC | DZ20: TRAFFIC W/DATA | EA20: QTY | EB20: GROSS | EC20: NETT | ED20: After Tax & CC | EE20: 0.036 | EF20: 0.03 | EG20: 0.024 | EH20: 0.012 | EI20: 0.006 | EJ20: DAILY TRAFFIC | EK20: TRAFFIC W/DATA | EL20: QTY | EM20: GROSS | EN20: NETT | EO20: After Tax & CC | EP20: 0.036 | EQ20: 0.03 | ER20: 0.024 | ES20: 0.012 | ET20: 0.006 | EU20: DAILY TRAFFIC | EV20: TRAFFIC W/DATA | EW20: QTY | EX20: GROSS | EY20: NETT | EZ20: After Tax & CC | FA20: 0.036 | FB20: 0.03 | FC20: 0.024 | FD20: 0.012 | FE20: 0.006 | FF20: DAILY TRAFFIC | FG20: TRAFFIC W/DATA | FH20: QTY | FI20: GROSS | FJ20: NETT | FK20: After Tax & CC | FL20: 0.036 | FM20: 0.03 | FN20: 0.024 | FO20: 0.012 | FP20: 0.006 | FQ20: DAILY TRAFFIC | FR20: TRAFFIC W/DATA
A21: =DS!B3 -> 46266 | FS21: QTY | FT21: GROSS | FU21: NETT | FV21: AFTER TAX&CC | FW21: Achievement
A22: 1 | X22: 1 | AK22: 1 | CG22: 1 | CH22: 1 | FQ22: =SUM(FF22+EJ22+DY22+DN22+DC22+CR22+CG22+BV22+BK22+AV22+AK22+X22+M22+B22) -> 3 | FR22: =C22+N22+Y22+AL22+AW22+BL22+BW22+CH22+CS22+DD22+DO22+DZ22+EK22+FG22 -> 1 | FS22: =SUM(FH22+EL22+EA22+DP22+DE22+CT22+CI22+BX22+BM22+AX22+AM22+Z22+O22+D22) -> 0 | FT22: =SUM(FI22+EM22+EB22+DQ22+DF22+CU22+CJ22+BY22+BN22+AY22+AN22+AA22+P22+E22) -> 0 | FU22: =SUM(FJ22+EN22+EC22+DR22+DG22+CV22+CK22+BZ22+BO22+AZ22+AO22+AB22+Q22+F22) -> 0 | FV22: =SUM(FK22+EO22+ED22+DS22+DH22+CW22+CL22+CA22+BP22+BA22+AP22+AC22+R22+G22) -> 0 | FW22: =FV22 -> 0
A23: 2 | M23: 1 | N23: 1 | X23: 1 | Y23: 1 | Z23: 1 | AA23: =DS!Q8 -> 174500000 | AB23: =DS!S8 -> 174500000 | AC23: =DS!AC8 -> 1.5720721e+08 | AG23: =DS!AC8 -> 1.5720721e+08 | AV23: 1 | AW23: 1 | BK23: 1 | BL23: 1 | CG23: 1 | CH23: 1 | CR23: 1 | CS23: 1 | FQ23: =SUM(FF23+EJ23+DY23+DN23+DC23+CR23+CG23+BV23+BK23+AV23+AK23+X23+M23+B23) -> 6 | FR23: =C23+N23+Y23+AL23+AW23+BL23+BW23+CH23+CS23+DD23+DO23+DZ23+EK23+FG23 -> 6 | FS23: =SUM(FH23+EL23+EA23+DP23+DE23+CT23+CI23+BX23+BM23+AX23+AM23+Z23+O23+D23) -> 1 | FT23: =SUM(FI23+EM23+EB23+DQ23+DF23+CU23+CJ23+BY23+BN23+AY23+AN23+AA23+P23+E23) -> 174500000 | FU23: =SUM(FJ23+EN23+EC23+DR23+DG23+CV23+CK23+BZ23+BO23+AZ23+AO23+AB23+Q23+F23) -> 174500000 | FV23: =SUM(FK23+EO23+ED23+DS23+DH23+CW23+CL23+CA23+BP23+BA23+AP23+AC23+R23+G23) -> 1.5720721e+08 | FW23: =FV23 -> 1.5720721e+08
A24: 3 | M24: 1 | N24: 1 | O24: 1 | P24: =DS!Q26 -> 273000000 | Q24: =DS!S26 -> 273000000 | R24: =DS!AC26 -> 2.4594595e+08 | T24: =DS!AC26 -> 2.4594595e+08 | X24: 1 | Y24: 1 | AK24: 1 | AL24: 1 | AM24: 1 | AN24: =DS!Q12 -> 107900000 | AO24: =DS!S12 -> 107900000 | AP24: =DS!AC12 -> 97207207 | AR24: =DS!AC12 -> 97207207 | AV24: 1 | AW24: 1 | AX24: 4 | AY24: =DS!Q15+DS!Q16+DS!Q17+DS!Q18 -> 1004300000 | AZ24: =DS!S15+DS!S16+DS!S17+DS!S18 -> 1004300000 | BA24: =DS!AC15+DS!AC16+DS!AC17+DS!AC18 -> 9.0477477e+08 | BF24: =DS!AC15+DS!AC16+DS!AC17+DS!AC18 -> 9.0477477e+08 | BK24: 1 | BL24: 1 | BM24: 1 | BN24: =DS!Q22 -> 574000000 | BO24: =DS!S22 -> 574000000 | BP24: =DS!AC22 -> 5.1711712e+08 | BR24: =DS!AC22 -> 5.1711712e+08 | BV24: 1 | BW24: 1 | CG24: 1 | CH24: 1 | CR24: 2 | CS24: 1 | FQ24: =SUM(FF24+EJ24+DY24+DN24+DC24+CR24+CG24+BV24+BK24+AV24+AK24+X24+M24+B24) -> 9 | FR24: =C24+N24+Y24+AL24+AW24+BL24+BW24+CH24+CS24+DD24+DO24+DZ24+EK24+FG24 -> 8 | FS24: =SUM(FH24+EL24+EA24+DP24+DE24+CT24+CI24+BX24+BM24+AX24+AM24+Z24+O24+D24) -> 7 | FT24: =SUM(FI24+EM24+EB24+DQ24+DF24+CU24+CJ24+BY24+BN24+AY24+AN24+AA24+P24+E24) -> 1959200000 | FU24: =SUM(FJ24+EN24+EC24+DR24+DG24+CV24+CK24+BZ24+BO24+AZ24+AO24+AB24+Q24+F24) -> 1959200000 | FV24: =SUM(FK24+EO24+ED24+DS24+DH24+CW24+CL24+CA24+BP24+BA24+AP24+AC24+R24+G24) -> 1.765045e+09 | FW24: =FV24 -> 1.765045e+09
A25: 4 | X25: 3 | Y25: 3 | AK25: 1 | AL25: 1 | AM25: 2 | AN25: =DS!Q30+DS!Q31 -> 1656100000 | AO25: =DS!S30+DS!S31 -> 1490490000 | AP25: =DS!AC30+DS!AC31 -> 1.3427838e+09 | AT25: =DS!AC30+DS!AC31 -> 1.3427838e+09 | BK25: 4 | BL25: 4 | BM25: 1 | BN25: =SMI!Q7 -> 235200000 | BO25: =SMI!S7 -> 235200000 | BP25: =SMI!AB7 -> 2.1189189e+08 | CR25: 2 | CS25: 2 | FQ25: =SUM(FF25+EJ25+DY25+DN25+DC25+CR25+CG25+BV25+BK25+AV25+AK25+X25+M25+B25) -> 10 | FR25: =C25+N25+Y25+AL25+AW25+BL25+BW25+CH25+CS25+DD25+DO25+DZ25+EK25+FG25 -> 10 | FS25: =SUM(FH25+EL25+EA25+DP25+DE25+CT25+CI25+BX25+BM25+AX25+AM25+Z25+O25+D25) -> 3 | FT25: =SUM(FI25+EM25+EB25+DQ25+DF25+CU25+CJ25+BY25+BN25+AY25+AN25+AA25+P25+E25) -> 1891300000 | FU25: =SUM(FJ25+EN25+EC25+DR25+DG25+CV25+CK25+BZ25+BO25+AZ25+AO25+AB25+Q25+F25) -> 1725690000 | FV25: =SUM(FK25+EO25+ED25+DS25+DH25+CW25+CL25+CA25+BP25+BA25+AP25+AC25+R25+G25) -> 1.5546757e+09 | FW25: =FV25 -> 1.5546757e+09
A26: 5 | X26: 2 | Y26: 1 | AK26: 1 | AV26: 2 | AW26: 2 | AX26: 5 | AY26: =DS!Q40+DS!Q51+DS!Q52+DS!Q53+DS!Q54 -> 523700000 | AZ26: =DS!S40+DS!S51+DS!S52+DS!S53+DS!S54 -> 523700000 | BA26: =DS!AC40+DS!AC51+DS!AC52+DS!AC53+DS!AC54 -> 4.718018e+08 | BC26: =DS!AC40 -> 1.3720721e+08 | BF26: =DS!AC51+DS!AC52+DS!AC53+DS!AC54 -> 3.3459459e+08 | BV26: 3 | BW26: 2 | BX26: 2 | BY26: =DS!Q36+DS!Q37 -> 48820000 | BZ26: =DS!S36+DS!S37 -> 48820000 | CA26: =DS!AC36+DS!AC37 -> 43981982 | CC26: =DS!AC37 -> 42072072 | CG26: 2 | CH26: 2 | CI26: 2 | CJ26: =DS!Q45+DS!Q48 -> 150400000 | CK26: =DS!S45+DS!S48 -> 150400000 | CL26: =DS!AC45+DS!AC48 -> 1.354955e+08 | CN26: =DS!AC45+DS!AC48 -> 1.354955e+08 | DC26: 2 | DD26: 2 | FQ26: =FF26+EJ26+DY26+DN26+DC26+CR26+CG26+BV26+BK26+AV26+AK26+X26+M26+B26 -> 12 | FR26: =C26+N26+Y26+AL26+AW26+BL26+BW26+CH26+CS26+DD26+DO26+DZ26+EK26+FG26 -> 9 | FS26: =SUM(FH26+EL26+EA26+DP26+DE26+CT26+CI26+BX26+BM26+AX26+AM26+Z26+O26+D26) -> 9 | FT26: =SUM(FI26+EM26+EB26+DQ26+DF26+CU26+CJ26+BY26+BN26+AY26+AN26+AA26+P26+E26) -> 722920000 | FU26: =SUM(FJ26+EN26+EC26+DR26+DG26+CV26+CK26+BZ26+BO26+AZ26+AO26+AB26+Q26+F26) -> 722920000 | FV26: =SUM(FK26+EO26+ED26+DS26+DH26+CW26+CL26+CA26+BP26+BA26+AP26+AC26+R26+G26) -> 6.5127928e+08 | FW26: =FV26 -> 6.5127928e+08
A27: 6 | M27: 2 | N27: 2 | O27: 1 | P27: =DS!Q58 -> 371000000 | Q27: =DS!S58 -> 371000000 | R27: =DS!AC58 -> 3.3423423e+08 | T27: =DS!AC58 -> 3.3423423e+08 | AV27: 5 | AW27: 3 | AX27: 1 | AY27: =DS!Q64 -> 107900000 | AZ27: =DS!S64 -> 107900000 | BA27: =DS!AC64 -> 97207207 | BF27: =DS!AC64 -> 97207207 | BK27: 6 | BL27: 5 | BV27: 2 | BW27: 2 | BX27: 2 | BY27: =DS!Q60+DS!Q72 -> 230100000 | BZ27: =DS!S60+DS!S72 -> 230100000 | CA27: =DS!AC60+DS!AC72 -> 2.072973e+08 | CC27: =DS!AC60+DS!AC72 -> 2.072973e+08 | CG27: 2 | CH27: 2 | CI27: 1 | CJ27: =DS!Q68 -> 76100000 | CK27: =DS!S68 -> 76100000 | CL27: =DS!AC68 -> 68558559 | CN27: =DS!AC68 -> 68558559 | DC27: 4 | DD27: 4 | FQ27: =SUM(FF27+EJ27+DY27+DN27+DC27+CR27+CG27+BV27+BK27+AV27+AK27+X27+M27+B27) -> 21 | FR27: =C27+N27+Y27+AL27+AW27+BL27+BW27+CH27+CS27+DD27+DO27+DZ27+EK27+FG27 -> 18 | FS27: =SUM(FH27+EL27+EA27+DP27+DE27+CT27+CI27+BX27+BM27+AX27+AM27+Z27+O27+D27) -> 5 | FT27: =SUM(FI27+EM27+EB27+DQ27+DF27+CU27+CJ27+BY27+BN27+AY27+AN27+AA27+P27+E27) -> 785100000 | FU27: =SUM(FJ27+EN27+EC27+DR27+DG27+CV27+CK27+BZ27+BO27+AZ27+AO27+AB27+Q27+F27) -> 785100000 | FV27: =SUM(FK27+EO27+ED27+DS27+DH27+CW27+CL27+CA27+BP27+BA27+AP27+AC27+R27+G27) -> 7.072973e+08 | FW27: =FV27 -> 7.072973e+08
A28: 7 | X28: 1 | Y28: 1 | BK28: 2 | BL28: 2 | BM28: 1 | BN28: =DS!Q75 -> 75100000 | BO28: =DS!S75 -> 75100000 | BP28: =DS!AC75 -> 67657658 | BR28: =DS!AC75 -> 67657658 | DC28: 3 | DD28: 3 | DE28: 2 | DF28: =DS!Q78+DS!Q81 -> 172900000 | DG28: =DS!S78+DS!S81 -> 172900000 | DH28: =DS!AC78+DS!AC81 -> 1.5576577e+08 | DJ28: =DS!AC78+DS!AC81 -> 1.5576577e+08 | FQ28: =SUM(FF28+EJ28+DY28+DN28+DC28+CR28+CG28+BV28+BK28+AV28+AK28+X28+M28+B28) -> 6 | FR28: =C28+N28+Y28+AL28+AW28+BL28+BW28+CH28+CS28+DD28+DO28+DZ28+EK28+FG28 -> 6 | FS28: =SUM(FH28+EL28+EA28+DP28+DE28+CT28+CI28+BX28+BM28+AX28+AM28+Z28+O28+D28) -> 3 | FT28: =SUM(FI28+EM28+EB28+DQ28+DF28+CU28+CJ28+BY28+BN28+AY28+AN28+AA28+P28+E28) -> 248000000 | FU28: =SUM(FJ28+EN28+EC28+DR28+DG28+CV28+CK28+BZ28+BO28+AZ28+AO28+AB28+Q28+F28) -> 248000000 | FV28: =SUM(FK28+EO28+ED28+DS28+DH28+CW28+CL28+CA28+BP28+BA28+AP28+AC28+R28+G28) -> 2.2342342e+08 | FW28: =FV28 -> 2.2342342e+08
A29: 8 | X29: 1 | Y29: 1 | Z29: 1 | AA29: =DS!Q87 -> 67500000 | AB29: =DS!S87 -> 67500000 | AC29: =DS!AC87 -> 60810811 | AG29: =DS!AC87 -> 60810811 | AK29: 2 | AL29: 1 | BV29: 1 | BW29: 1 | CG29: 1 | CH29: 1 | CI29: 1 | CJ29: =DS!Q84 -> 813700000 | CK29: =DS!S84 -> 773015000 | CL29: =DS!AC84 -> 6.9640991e+08 | CP29: =DS!AC84 -> 6.9640991e+08 | CR29: 2 | CS29: 2 | FQ29: =SUM(FF29+EJ29+DY29+DN29+DC29+CR29+CG29+BV29+BK29+AV29+AK29+X29+M29+B29) -> 7 | FR29: =C29+N29+Y29+AL29+AW29+BL29+BW29+CH29+CS29+DD29+DO29+DZ29+EK29+FG29 -> 6 | FS29: =SUM(FH29+EL29+EA29+DP29+DE29+CT29+CI29+BX29+BM29+AX29+AM29+Z29+O29+D29) -> 2 | FT29: =SUM(FI29+EM29+EB29+DQ29+DF29+CU29+CJ29+BY29+BN29+AY29+AN29+AA29+P29+E29) -> 881200000 | FU29: =SUM(FJ29+EN29+EC29+DR29+DG29+CV29+CK29+BZ29+BO29+AZ29+AO29+AB29+Q29+F29) -> 840515000 | FV29: =SUM(FK29+EO29+ED29+DS29+DH29+CW29+CL29+CA29+BP29+BA29+AP29+AC29+R29+G29) -> 7.5722072e+08 | FW29: =FV29 -> 7.5722072e+08
A30: 9 | M30: 1 | X30: 1 | Y30: 1 | Z30: 1 | AA30: =DS!Q93 -> 121500000 | AB30: =DS!S93 -> 121500000 | AC30: =DS!AC93 -> 1.0945946e+08 | AG30: =DS!AC93 -> 1.0945946e+08 | AK30: 1 | AV30: 1 | BK30: 2 | BL30: 1 | BM30: 1 | BN30: =DS!Q96 -> 76100000 | BO30: =DS!S96 -> 76100000 | BP30: =DS!AC96 -> 68558559 | BR30: =DS!AC96 -> 68558559 | BV30: 1 | CG30: 2 | CH30: 2 | CI30: 1 | CJ30: =DS!Q90 -> 1601600000 | CK30: =DS!S90 -> 1435000000 | CL30: =DS!AC90 -> 1.2927928e+09 | CO30: =DS!AC90 -> 1.2927928e+09 | DC30: 2 | DD30: 1 | FQ30: =SUM(FF30+EJ30+DY30+DN30+DC30+CR30+CG30+BV30+BK30+AV30+AK30+X30+M30+B30) -> 11 | FR30: =C30+N30+Y30+AL30+AW30+BL30+BW30+CH30+CS30+DD30+DO30+DZ30+EK30+FG30 -> 5 | FS30: =SUM(FH30+EL30+EA30+DP30+DE30+CT30+CI30+BX30+BM30+AX30+AM30+Z30+O30+D30+EW30) -> 3 | FT30: =SUM(FI30+EM30+EB30+DQ30+DF30+CU30+CJ30+BY30+BN30+AY30+AN30+AA30+P30+E30+EX30) -> 1799200000 | FU30: =SUM(FJ30+EN30+EC30+DR30+DG30+CV30+CK30+BZ30+BO30+AZ30+AO30+AB30+Q30+F30+EY30) -> 1632600000 | FV30: =SUM(FK30+EO30+ED30+DS30+DH30+CW30+CL30+CA30+BP30+BA30+AP30+AC30+R30+G30+EZ30) -> 1.4708108e+09 | FW30: =FV30 -> 1.4708108e+09
A31: 10 | M31: 1 | AV31: 1 | AW31: 1 | AX31: 1 | AY31: =DS!Q99 -> 76100000 | AZ31: =DS!S99 -> 76100000 | BA31: =DS!AC99 -> 68558559 | BF31: =DS!AC99 -> 68558559 | BK31: 1 | BL31: 1 | BM31: 1 | BN31: =DS!Q102 -> 42400000 | BO31: =DS!S102 -> 42400000 | BP31: =DS!AC102 -> 38198198 | BR31: =DS!AC102 -> 38198198 | BV31: 1 | BW31: 1 | BX31: 1 | BY31: =DS!Q108 -> 85800000 | BZ31: =DS!S108 -> 85800000 | CA31: =DS!AC108 -> 77297297 | CC31: =DS!AC108 -> 77297297 | DC31: 3 | DD31: 3 | DE31: 2 | DF31: =DS!Q105+DS!Q106 -> 223900000 | DG31: =DS!S105+DS!S106 -> 223900000 | DH31: =DS!AC105+DS!AC106 -> 2.0171171e+08 | DJ31: =DS!AC105+DS!AC106 -> 2.0171171e+08 | FQ31: =SUM(FF31+EJ31+DY31+DN31+DC31+CR31+CG31+BV31+BK31+AV31+AK31+X31+M31+B31) -> 7 | FR31: =C31+N31+Y31+AL31+AW31+BL31+BW31+CH31+CS31+DD31+DO31+DZ31+EK31+FG31 -> 6 | FS31: =SUM(FH31+EL31+EA31+DP31+DE31+CT31+CI31+BX31+BM31+AX31+AM31+Z31+O31+D31) -> 5 | FT31: =SUM(FI31+EM31+EB31+DQ31+DF31+CU31+CJ31+BY31+BN31+AY31+AN31+AA31+P31+E31) -> 428200000 | FU31: =SUM(FJ31+EN31+EC31+DR31+DG31+CV31+CK31+BZ31+BO31+AZ31+AO31+AB31+Q31+F31) -> 428200000 | FV31: =SUM(FK31+EO31+ED31+DS31+DH31+CW31+CL31+CA31+BP31+BA31+AP31+AC31+R31+G31) -> 3.8576577e+08 | FW31: =FV31 -> 3.8576577e+08
A32: 11 | X32: 2 | Y32: 1 | Z32: 1 | AA32: =DS!Q115 -> 106000000 | AB32: =DS!S115 -> 106000000 | AC32: =DS!AC115 -> 95495495 | AG32: =DS!AC115 -> 95495495 | AK32: 1 | AL32: 1 | AV32: 2 | AW32: 1 | CG32: 1 | CH32: 1 | CI32: 1 | CJ32: =DS!Q119 -> 100300000 | CK32: =DS!S119 -> 100300000 | CL32: =DS!AC119 -> 90360360 | CN32: =DS!AC119 -> 90360360 | CR32: 1 | CS32: 1 | CT32: 1 | CU32: =DS!Q111 -> 77000000 | CV32: =DS!S111 -> 77000000 | CW32: =DS!AC111 -> 69369369 | CY32: =DS!AC111 -> 69369369 | FQ32: =SUM(FF32+EJ32+DY32+DN32+DC32+CR32+CG32+BV32+BK32+AV32+AK32+X32+M32+B32) -> 7 | FR32: =C32+N32+Y32+AL32+AW32+BL32+BW32+CH32+CS32+DD32+DO32+DZ32+EK32+FG32 -> 5 | FS32: =SUM(FH32+EL32+EA32+DP32+DE32+CT32+CI32+BX32+BM32+AX32+AM32+Z32+O32+D32) -> 3 | FT32: =SUM(FI32+EM32+EB32+DQ32+DF32+CU32+CJ32+BY32+BN32+AY32+AN32+AA32+P32+E32) -> 283300000 | FU32: =SUM(FJ32+EN32+EC32+DR32+DG32+CV32+CK32+BZ32+BO32+AZ32+AO32+AB32+Q32+F32) -> 283300000 | FV32: =SUM(FK32+EO32+ED32+DS32+DH32+CW32+CL32+CA32+BP32+BA32+AP32+AC32+R32+G32) -> 2.5522523e+08 | FW32: =FV32 -> 2.5522523e+08
A33: 12 | M33: 3 | N33: 3 | X33: 3 | Y33: 3 | Z33: 1 | AA33: =DS!Q130 -> 51700000 | AB33: =DS!S130 -> 51700000 | AC33: =DS!AC130 -> 46576577 | AG33: =DS!AC130 -> 46576577 | AK33: 2 | AL33: 2 | AV33: 1 | AW33: 1 | BK33: 2 | BL33: 2 | BV33: 2 | BW33: 1 | CG33: 3 | CH33: 3 | CI33: 2 | CJ33: =DS!Q125+DS!Q128 -> 79200000 | CK33: =DS!S125+DS!S128 -> 79200000 | CL33: =DS!AC125+DS!AC128 -> 71351351 | CN33: =DS!AC125+DS!AC128 -> 71351351 | DC33: 5 | DD33: 5 | FQ33: =SUM(FF33+EJ33+DY33+DN33+DC33+CR33+CG33+BV33+BK33+AV33+AK33+X33+M33+B33) -> 21 | FR33: =C33+N33+Y33+AL33+AW33+BL33+BW33+CH33+CS33+DD33+DO33+DZ33+EK33+FG33 -> 20 | FS33: =SUM(FH33+EL33+EA33+DP33+DE33+CT33+CI33+BX33+BM33+AX33+AM33+Z33+O33+D33) -> 3 | FT33: =SUM(FI33+EM33+EB33+DQ33+DF33+CU33+CJ33+BY33+BN33+AY33+AN33+AA33+P33+E33) -> 130900000 | FU33: =SUM(FJ33+EN33+EC33+DR33+DG33+CV33+CK33+BZ33+BO33+AZ33+AO33+AB33+Q33+F33) -> 130900000 | FV33: =SUM(FK33+EO33+ED33+DS33+DH33+CW33+CL33+CA33+BP33+BA33+AP33+AC33+R33+G33) -> 1.1792793e+08 | FW33: =FV33 -> 1.1792793e+08
A34: 13 | M34: 2 | N34: 2 | AV34: 3 | AW34: 1 | BV34: 5 | BW34: 4 | CG34: 2 | CH34: 2 | CR34: 4 | CS34: 2 | CT34: 1 | CU34: =DS!Q133 -> 3220000 | CV34: =DS!S133 -> 3220000 | CW34: =DS!AC133 -> 2900900.9 | DC34: 4 | DD34: 2 | DE34: 1 | DF34: =DS!Q135 -> 9800000 | DG34: =DS!S135 -> 9800000 | DH34: =DS!AC135 -> 8828828.8 | DJ34: =DS!AC135 -> 8828828.8 | FQ34: =SUM(FF34+EJ34+DY34+DN34+DC34+CR34+CG34+BV34+BK34+AV34+AK34+X34+M34+H35) -> 20 | FR34: =C34+N34+Y34+AL34+AW34+BL34+BW34+CH34+CS34+DD34+DO34+DZ34+EK34+FG34 -> 13 | FS34: =SUM(FH34+EL34+EA34+DP34+DE34+CT34+CI34+BX34+BM34+AX34+AM34+Z34+O34+I35) -> 2 | FT34: =SUM(FI34+EM34+EB34+DQ34+DF34+CU34+CJ34+BY34+BN34+AY34+AN34+AA34+P34+E34) -> 13020000 | FU34: =SUM(FJ34+EN34+EC34+DR34+DG34+CV34+CK34+BZ34+BO34+AZ34+AO34+AB34+Q34+F34) -> 13020000 | FV34: =SUM(FK34+EO34+ED34+DS34+DH34+CW34+CL34+CA34+BP34+BA34+AP34+AC34+R34+G34) -> 11729730 | FW34: =FV34 -> 11729730
A35: 14 | M35: 1 | X35: 1 | Y35: 1 | BV35: 1 | DC35: 1 | DD35: 1 | FQ35: =SUM(FF35+EJ35+DY35+DN35+DC35+CR35+CG35+BV35+BK35+AV35+AK35+X35+M35+B35) -> 4 | FR35: =C35+N35+Y35+AL35+AW35+BL35+BW35+CH35+CS35+DD35+DO35+DZ35+EK35+FG35 -> 2 | FS35: =SUM(FH35+EL35+EA35+DP35+DE35+CT35+CI35+BX35+BM35+AX35+AM35+Z35+O35+D35) -> 0 | FT35: =SUM(FI35+EM35+EB35+DQ35+DF35+CU35+CJ35+BY35+BN35+AY35+AN35+AA35+P35+E35) -> 0 | FU35: =SUM(FJ35+EN35+EC35+DR35+DG35+CV35+CK35+BZ35+BO35+AZ35+AO35+AB35+Q35+F35) -> 0 | FV35: =SUM(FK35+EO35+ED35+DS35+DH35+CW35+CL35+CA35+BP35+BA35+AP35+AC35+R35+G35) -> 0 | FW35: =FV35 -> 0
A36: 15 | M36: 1 | N36: 1 | O36: 1 | P36: =DS!Q138 -> 58700000 | Q36: =DS!S138 -> 58700000 | R36: =DS!AC138 -> 52882883 | T36: =DS!AC138 -> 52882883 | X36: 1 | Y36: 1 | AV36: 2 | AW36: 2 | AX36: 2 | AY36: =DS!Q144+DS!Q147 -> 132500000 | AZ36: =DS!S144+DS!S147 -> 132500000 | BA36: =DS!AC144+DS!AC147 -> 1.1936937e+08 | BF36: =DS!AC144+DS!AC147 -> 1.1936937e+08 | BK36: 2 | BL36: 1 | CR36: 2 | CS36: 1 | CT36: 1 | CU36: =DS!Q141 -> 36800000 | CV36: =DS!S141 -> 36800000 | CW36: =DS!AC141 -> 33153153 | CY36: =DS!AC141 -> 33153153 | FQ36: =SUM(FF36+EJ36+DY36+DN36+DC36+CR36+CG36+BV36+BK36+AV36+AK36+X36+M36+B36) -> 8 | FR36: =C36+N36+Y36+AL36+AW36+BL36+BW36+CH36+CS36+DD36+DO36+DZ36+EK36+FG36 -> 6 | FS36: =SUM(FH36+EL36+EA36+DP36+DE36+CT36+CI36+BX36+BM36+AX36+AM36+Z36+O36+D36) -> 4 | FT36: =SUM(FI36+EM36+EB36+DQ36+DF36+CU36+CJ36+BY36+BN36+AY36+AN36+AA36+P36+E36) -> 228000000 | FU36: =SUM(FJ36+EN36+EC36+DR36+DG36+CV36+CK36+BZ36+BO36+AZ36+AO36+AB36+Q36+F36) -> 228000000 | FV36: =SUM(FK36+EO36+ED36+DS36+DH36+CW36+CL36+CA36+BP36+BA36+AP36+AC36+R36+G36) -> 2.0540541e+08 | FW36: =FV36 -> 2.0540541e+08
A37: 16 | M37: 2 | N37: 2 | AV37: 1 | AW37: 1 | BK37: 1 | BL37: 1 | CR37: 2 | CS37: 2 | CT37: 1 | CU37: =DS!Q151 -> 159500000 | CV37: =DS!S151 -> 159500000 | CW37: =DS!AC151 -> 1.4369369e+08 | CY37: =DS!AC151 -> 1.4369369e+08 | DC37: 2 | DD37: 2 | DE37: 1 | DF37: =DS!Q155 -> 144500000 | DG37: =DS!S155 -> 144500000 | DH37: =DS!AC155 -> 1.3018018e+08 | DJ37: =DS!AC155 -> 1.3018018e+08 | DN37: 1 | DO37: 1 | DP37: 1 | DQ37: =DS!Q159 -> 58700000 | DR37: =DS!S159 -> 58700000 | DS37: =DS!AC159 -> 52882883 | DU37: =DS!AC159 -> 52882883 | FQ37: =SUM(FF37+EJ37+DY37+DN37+DC37+CR37+CG37+BV37+BK37+AV37+AK37+X37+M37+B37) -> 9 | FR37: =C37+N37+Y37+AL37+AW37+BL37+BW37+CH37+CS37+DD37+DO37+DZ37+EK37+FG37 -> 9 | FS37: =SUM(FH37+EL37+EA37+DP37+DE37+CT37+CI37+BX37+BM37+AX37+AM37+Z37+O37+D37+EW37) -> 3 | FT37: =SUM(FI37+EM37+EB37+DQ37+DF37+CU37+CJ37+BY37+BN37+AY37+AN37+AA37+P37+E37+EX37) -> 362700000 | FU37: =SUM(FJ37+EN37+EC37+DR37+DG37+CV37+CK37+BZ37+BO37+AZ37+AO37+AB37+Q37+F37+EY37) -> 362700000 | FV37: =SUM(FK37+EO37+ED37+DS37+DH37+CW37+CL37+CA37+BP37+BA37+AP37+AC37+R37+G37+EZ37) -> 3.2675676e+08 | FW37: =FV37 -> 3.2675676e+08
A38: 17 | M38: 2 | N38: 2 | O38: 2 | P38: =DS!Q162+DS!Q163 -> 41600000 | Q38: =DS!S162+DS!S163 -> 41600000 | R38: =DS!AC162+DS!AC163 -> 37477477 | T38: =DS!AC162+DS!AC163 -> 37477477 | BV38: 1 | BW38: 1 | BX38: 1 | BY38: =DS!Q165 -> 262500000 | BZ38: =DS!S165 -> 262500000 | CA38: =DS!AC165 -> 2.3648649e+08 | CC38: =DS!AC165 -> 2.3648649e+08 | DC38: 2 | DD38: 2 | FQ38: =SUM(FF38+EJ38+DY38+DN38+DC38+CR38+CG38+BV38+BK38+AV38+AK38+X38+M38+B38) -> 5 | FR38: =C38+N38+Y38+AL38+AW38+BL38+BW38+CH38+CS38+DD38+DO38+DZ38+EK38+FG38 -> 5 | FS38: =SUM(FH38+EL38+EA38+DP38+DE38+CT38+CI38+BX38+BM38+AX38+AM38+Z38+O38+D38+EW38) -> 3 | FT38: =SUM(FI38+EM38+EB38+DQ38+DF38+CU38+CJ38+BY38+BN38+AY38+AN38+AA38+P38+E38+EX38) -> 304100000 | FU38: =SUM(FJ38+EN38+EC38+DR38+DG38+CV38+CK38+BZ38+BO38+AZ38+AO38+AB38+Q38+F38+EY38) -> 304100000 | FV38: =SUM(FK38+EO38+ED38+DS38+DH38+CW38+CL38+CA38+BP38+BA38+AP38+AC38+R38+G38+EZ38) -> 2.7396396e+08 | FW38: =FV38 -> 2.7396396e+08
A39: 18 | X39: 2 | Y39: 1 | Z39: 1 | AA39: =DS!Q171 -> 91700000 | AB39: =DS!S171 -> 91700000 | AC39: =DS!AC171 -> 82612613 | AG39: =DS!AC171 -> 82612613 | AV39: 1 | AW39: 1 | BK39: 1 | BL39: 1 | BM39: 1 | BN39: =DS!Q177 -> 206000000 | BO39: =DS!S177 -> 206000000 | BP39: =DS!AC177 -> 1.8558559e+08 | BR39: =DS!AC177 -> 1.8558559e+08 | CR39: 1 | CS39: 1 | DC39: 2 | DD39: 2 | DE39: 2 | DF39: =DS!Q168+DS!Q174 -> 252700000 | DG39: =DS!S168+DS!S174 -> 252700000 | DH39: =DS!AC168+DS!AC174 -> 2.2765766e+08 | DJ39: =DS!AC168+DS!AC174 -> 2.2765766e+08 | FQ39: =SUM(FF39+EJ39+DY39+DN39+DC39+CR39+CG39+BV39+BK39+AV39+AK39+X39+M39+B39) -> 7 | FR39: =C39+N39+Y39+AL39+AW39+BL39+BW39+CH39+CS39+DD39+DO39+DZ39+EK39+FG39 -> 6 | FS39: =SUM(FH39+EL39+EA39+DP39+DE39+CT39+CI39+BX39+BM39+AX39+AM39+Z39+O39+D39) -> 4 | FT39: =SUM(FI39+EM39+EB39+DQ39+DF39+CU39+CJ39+BY39+BN39+AY39+AN39+AA39+P39+E39) -> 550400000 | FU39: =SUM(FJ39+EN39+EC39+DR39+DG39+CV39+CK39+BZ39+BO39+AZ39+AO39+AB39+Q39+F39) -> 550400000 | FV39: =SUM(FK39+EO39+ED39+DS39+DH39+CW39+CL39+CA39+BP39+BA39+AP39+AC39+R39+G39) -> 4.9585586e+08 | FW39: =FV39 -> 4.9585586e+08
A40: 19 | M40: 2 | N40: 2 | X40: 2 | Y40: 2 | AK40: 2 | AL40: 2 | AM40: 2 | AN40: =DS!Q186+DS!Q189 -> 145200000 | AO40: =DS!S186+DS!S189 -> 145200000 | AP40: =DS!AC186+DS!AC189 -> 1.3081081e+08 | AR40: =DS!AC186+DS!AC189 -> 1.3081081e+08 | BK40: 2 | BL40: 2 | BM40: 1 | BN40: =DS!Q180 -> 65500000 | BO40: =DS!S180 -> 65500000 | BP40: =DS!AC180 -> 59009009 | BR40: =DS!AC180 -> 59009009 | BV40: 2 | BW40: 2 | CG40: 1 | CH40: 1 | DC40: 3 | DD40: 2 | DE40: 1 | DF40: =DS!Q183 -> 36800000 | DG40: =DS!S183 -> 36800000 | DH40: =DS!AC183 -> 33153153 | DJ40: =DS!AC183 -> 33153153 | FQ40: =SUM(FF40+EJ40+DY40+DN40+DC40+CR40+CG40+BV40+BK40+AV40+AK40+X40+M40+B40) -> 14 | FR40: =C40+N40+Y40+AL40+AW40+BL40+BW40+CH40+CS40+DD40+DO40+DZ40+EK40+FG40 -> 13 | FS40: =SUM(FH40+EL40+EA40+DP40+DE40+CT40+CI40+BX40+BM40+AX40+AM40+Z40+O40+D40) -> 4 | FT40: =SUM(FI40+EM40+EB40+DQ40+DF40+CU40+CJ40+BY40+BN40+AY40+AN40+AA40+P40+E40) -> 247500000 | FU40: =SUM(FJ40+EN40+EC40+DR40+DG40+CV40+CK40+BZ40+BO40+AZ40+AO40+AB40+Q40+F40) -> 247500000 | FV40: =SUM(FK40+EO40+ED40+DS40+DH40+CW40+CL40+CA40+BP40+BA40+AP40+AC40+R40+G40) -> 2.2297297e+08 | FW40: =FV40 -> 2.2297297e+08
A41: 20 | M41: 2 | X41: 2 | Y41: 2 | AK41: 2 | AL41: 1 | BK41: 1 | BL41: 1 | BV41: 2 | BW41: 2 | CG41: 1 | CR41: 2 | CS41: 2 | FQ41: =SUM(FF41+EJ41+DY41+DN41+DC41+CR41+CG41+BV41+BK41+AV41+AK41+X41+M41+B41) -> 12 | FR41: =C41+N41+Y41+AL41+AW41+BL41+BW41+CH41+CS41+DD41+DO41+DZ41+EK41+FG41 -> 8 | FS41: =SUM(FH41+EL41+EA41+DP41+DE41+CT41+CI41+BX41+BM41+AX41+AM41+Z41+O41+D41) -> 0 | FT41: =SUM(FI41+EM41+EB41+DQ41+DF41+CU41+CJ41+BY41+BN41+AY41+AN41+AA41+P41+E41) -> 0 | FU41: =SUM(FJ41+EN41+EC41+DR41+DG41+CV41+CK41+BZ41+BO41+AZ41+AO41+AB41+Q41+F41) -> 0 | FV41: =SUM(FK41+EO41+ED41+DS41+DH41+CW41+CL41+CA41+BP41+BA41+AP41+AC41+R41+G41) -> 0 | FW41: =FV41 -> 0
A42: 21 | FQ42: =SUM(FF42+EJ42+DY42+DN42+DC42+CR42+CG42+BV42+BK42+AV42+AK42+X42+M42+B42) -> 0 | FR42: =C42+N42+Y42+AL42+AW42+BL42+BW42+CH42+CS42+DD42+DO42+DZ42+EK42+FG42 -> 0 | FS42: =SUM(FH42+EL42+EA42+DP42+DE42+CT42+CI42+BX42+BM42+AX42+AM42+Z42+O42+D42) -> 0 | FT42: =SUM(FI42+EM42+EB42+DQ42+DF42+CU42+CJ42+BY42+BN42+AY42+AN42+AA42+P42+E42) -> 0 | FU42: =SUM(FJ42+EN42+EC42+DR42+DG42+CV42+CK42+BZ42+BO42+AZ42+AO42+AB42+Q42+F42) -> 0 | FV42: =SUM(FK42+EO42+ED42+DS42+DH42+CW42+CL42+CA42+BP42+BA42+AP42+AC42+R42+G42) -> 0 | FW42: =FV42 -> 0
A43: 22 | FQ43: =SUM(FF43+EJ43+DY43+DN43+DC43+CR43+CG43+BV43+BK43+AV43+AK43+X43+M43+B43) -> 0 | FR43: =C43+N43+Y43+AL43+AW43+BL43+BW43+CH43+CS43+DD43+DO43+DZ43+EK43+FG43 -> 0 | FS43: =SUM(FH43+EL43+EA43+DP43+DE43+CT43+CI43+BX43+BM43+AX43+AM43+Z43+O43+D43) -> 0 | FT43: =SUM(FI43+EM43+EB43+DQ43+DF43+CU43+CJ43+BY43+BN43+AY43+AN43+AA43+P43+E43) -> 0 | FU43: =SUM(FJ43+EN43+EC43+DR43+DG43+CV43+CK43+BZ43+BO43+AZ43+AO43+AB43+Q43+F43) -> 0 | FV43: =SUM(FK43+EO43+ED43+DS43+DH43+CW43+CL43+CA43+BP43+BA43+AP43+AC43+R43+G43) -> 0 | FW43: =FV43 -> 0
A44: 23 | FQ44: =SUM(FF44+EJ44+DY44+DN44+DC44+CR44+CG44+BV44+BK44+AV44+AK44+X44+M44+B44) -> 0 | FR44: =C44+N44+Y44+AL44+AW44+BL44+BW44+CH44+CS44+DD44+DO44+DZ44+EK44+FG44 -> 0 | FS44: =SUM(FH44+EL44+EA44+DP44+DE44+CT44+CI44+BX44+BM44+AX44+AM44+Z44+O44+D44) -> 0 | FT44: =SUM(FI44+EM44+EB44+DQ44+DF44+CU44+CJ44+BY44+BN44+AY44+AN44+AA44+P44+E44) -> 0 | FU44: =SUM(FJ44+EN44+EC44+DR44+DG44+CV44+CK44+BZ44+BO44+AZ44+AO44+AB44+Q44+F44) -> 0 | FV44: =SUM(FK44+EO44+ED44+DS44+DH44+CW44+CL44+CA44+BP44+BA44+AP44+AC44+R44+G44) -> 0 | FW44: =FV44 -> 0
A45: 24 | FQ45: =SUM(FF45+EJ45+DY45+DN45+DC45+CR45+CG45+BV45+BK45+AV45+AK45+X45+M45+B45) -> 0 | FR45: =C45+N45+Y45+AL45+AW45+BL45+BW45+CH45+CS45+DD45+DO45+DZ45+EK45+FG45 -> 0 | FS45: =SUM(FH45+EL45+EA45+DP45+DE45+CT45+CI45+BX45+BM45+AX45+AM45+Z45+O45+D45) -> 0 | FT45: =SUM(FI45+EM45+EB45+DQ45+DF45+CU45+CJ45+BY45+BN45+AY45+AN45+AA45+P45+E45) -> 0 | FU45: =SUM(FJ45+EN45+EC45+DR45+DG45+CV45+CK45+BZ45+BO45+AZ45+AO45+AB45+Q45+F45) -> 0 | FV45: =SUM(FK45+EO45+ED45+DS45+DH45+CW45+CL45+CA45+BP45+BA45+AP45+AC45+R45+G45) -> 0 | FW45: =FV45 -> 0
...

Sheet Commission
A1: PT. MOGEMS PUTRI INTERNATIONAL | I1: Achievement Store | J1: =DS!AD328 -> 9.5825631e+09
